Workbook

Sheet みずほ銀行
A1: みずほ銀行
A3: 支払先 | B3: 勘定科目 | C3: ９月末 | D3: ８月末 | E3: ７月末 | F3: ６月末 | G3: 備考 | H3: 媒体
A4: 佐川急便 越谷 | B4: 通信費 | D4: 72056 | E4: 82367 | F4: 72308 | G4: みずほ第十集中 | H4: ダウンロード
A5: 佐川急便 所沢 | B5: 通信費 | D5: 2178 | H5: ダウンロード
A6: 佐川急便 横浜瀬谷 | B6: 通信費 | D6: 9974 | H6: ダウンロード
A7: アスクル(プラスロジテクス) | B7: 消耗品費 | D7: 160084 | E7: 102568 | F7: 93408 | G7: みずほ銀行 | H7: 郵送
B8: 消耗品費（8%） | E8: 66448
A9: レオパレス２１ | B9: 賃借料 | D9: 228360 | E9: 228360 | F9: 360195 | H9: ダウンロード
A10: レオパレスガス代 | B10: 水道光熱費 | D10: 14720 | E10: 18301 | F10: 17236 | H10: メール
A11: 住友林業アーキテクノ | B11: 修繕費 | D11: 35310 | G11: ガス管破損修繕費用負担 8/5振込 | H11: 郵送
A15: マサヨ(越谷) | B15: 賃借料 | C15: 382500 | D15: 382500 | E15: 382500 | F15: 382500 | G15: 駐車場 | H15: なし
A16: ヨシテル(越谷) | B16: 賃借料 | C16: 350000 | D16: 350000 | E16: 350000 | F16: 350000 | G16: 駐車場 | H16: なし
A17: ヨシテル(三郷) | B17: 賃借料 | C17: 390000 | D17: 390000 | E17: 390000 | F17: 390000 | G17: 駐車場 | H17: なし
A18: 中沢酒造株式会社 | B18: 賃借料 | C18: 60000 | D18: 60000 | E18: 60000 | F18: 60000 | G18: 前払い足柄店駐車場10台 | H18: なし
A19: 丸福企画 | B19: 賃借料 | C19: 170000 | D19: 170000 | E19: 170000 | F19: 170000 | G19: 駐車場 | H19: なし
A20: 豊田駐車場(孝司) | B20: 賃借料 | C20: 165000 | G20: 駐車場 | H20: なし
A21: 山脇土地 | B21: 賃借料 | C21: 55000 | G21: 駐車場 | H21: なし
A22: ヤナセ住販 | B22: 賃借料 | C22: 35200 | G22: 駐車場 | H22: なし
A23: 大栄不動産 | B23: 賃借料 | C23: 29700 | G23: 駐車場 | H23: なし
A24: 林 横浜駐車場 | B24: 賃借料 | C24: 90000 | G24: 駐車場 | H24: なし
A25: 大東建託 | B25: 賃借料 | C25: 67300 | G25: アパート | H25: なし
A26: 三郷中央クリニック | B26: 雑費 | C26: 60000 | G26: 産業医 | H26: なし
A30: 合計金額 | C30: =SUM(C4:C18) -> 1182500 | D30: =SUM(D4:D18) -> 1705182 | E30: =SUM(E4:E18) -> 1680544 | F30: =SUM(F4:F18) -> 1725647
D31: =D30-D11 -> 1669872 | G31: ガス管破損負担分を除いた額

Sheet 武蔵野銀行
A1: 取引先 | B1: 勘定科目 | C1: ９月末 | D1: ８月末 | E1: ７月末 | F1: ６月末 | G1: 備考 | H1: 媒体
A2: 小松車輛 | C2: =C3+C4 -> 0 | D2: =D3+D4 -> 978694 | E2: =E3+E4 -> 907610 | F2: =F3+F4 -> 849200 | H2: 郵送
B3: リース料 | D3: 849200 | E3: 849200 | F3: 849200 | G3: 車両リース
B4: 修繕費 | D4: 129494 | E4: 58410 | G4: 車両修理
A5: 梅田自動車 | C5: =C6+C7 -> 0 | D5: =D6+D7 -> 1649540 | E5: =E6+E7 -> 322350 | F5: =F6+F7 -> 815100 | H5: 郵送
B6: 修繕費 | D6: 1649540 | E6: 322350 | F6: 815100 | G6: 車両修理
B7: 車両運搬具
A8: ニシネン砿油（セルヴィス） | C8: =SUM(C9:C15) -> 0 | D8: =SUM(D9:D15) -> 339900 | E8: =SUM(E9:E15) -> 341600 | F8: =SUM(F9:F15) -> 0 | H8: 郵送
B9: 修繕費 | D9: 339900 | E9: 170800 | G9: 車両修理
B10: 保険料 | E10: 22400 | G10: 車検
B11: 租税公課
B12: 支払手数料 | E12: 23550
B13: 消耗品費 | E13: 124850
B14: 車両運搬具
B15: 車輛燃料費
A16: くるま屋 石本 | C16: =SUM(C17:C21) -> 0 | D16: =SUM(D17:D21) -> 90600 | E16: =SUM(E17:E21) -> 0 | F16: =SUM(F17:F21) -> 11300 | H16: 郵送
B17: 修繕費 | D17: 56760 | F17: 11300 | G17: 車両修理
B18: 保険料 | D18: 17540 | G18: 車検
B19: 租税公課 | D19: 7500
B20: 支払手数料 | D20: 8800
B21: 消耗品費
A22: 平田自動車工業㈱ | C22: =SUM(C23:C24) -> 0 | D22: =SUM(D23:D24) -> 0 | E22: =SUM(E23:E24) -> 0 | F22: =SUM(F23:F24) -> 5500 | H22: 郵送
B23: 修繕費 | F23: 5500 | G23: 車両修理
B24: 消耗品費
A25: ㈱オプティム | C25: =SUM(C26:C27) -> 0 | D25: =SUM(D26:D27) -> 89100 | E25: =SUM(E26:E27) -> 89100 | F25: =SUM(F26:F27) -> 89100 | H25: 郵送
B26: 雑費 | D26: 89100 | E26: 89100 | F26: 89100 | G26: GEOスキャンライセンス
B27: 工具、器具及び備品 | G27: GEOスキャン本体
A28: エムエス測器 | C28: =SUM(C29:C31) -> 0 | D28: =SUM(D29:D31) -> 60500 | E28: =SUM(E29:E31) -> 0 | F28: =SUM(F29:F31) -> 0 | H28: 郵送
B29: 修繕費 | D29: 46200
B30: 消耗品費 | D30: 14300
B31: 工具、器具及び備品
A32: 滝本特殊溶接工業 | C32: =SUM(C33:C34) -> 0 | D32: =SUM(D33:D34) -> 0 | E32: =SUM(E33:E34) -> 8250 | F32: =SUM(F33:F34) -> 34000 | G32: 地盤機器修理 | H32: 郵送
B33: 修繕費 | F33: 34000
B34: 消耗品費 | E34: 8250
A35: アンナカ | C35: =SUM(C36:C37) -> 0 | D35: =SUM(D36:D37) -> 461780 | E35: =SUM(E36:E37) -> 288893 | F35: =SUM(F36:F37) -> 190410 | H35: info@にメール
B36: 消耗品費 | D36: 461780 | E36: 288893 | F36: 190410
B37: 工具、器具及び備品 | G37: 測量機器
A38: GEプランニング | B38: 消耗品費 | E38: 550000 | G38: 地盤機器
A39: 日東精工 | B39: 修繕費 | D39: 485760 | F39: 685652 | G39: ジオカルテ修理 | H39: メール
A40: 埼玉測器社 | B40: 消耗品費 | D40: 155881 | E40: 103400 | F40: 79200 | G40: 測量機器 | H40: 郵送
...

Sheet 勘定科目
A1: 勘定科目別 月次支払合計
A2: ※ 各セルは SUMIFS 式です。明細シート（みずほ銀行・武蔵野銀行）のB列「勘定科目」と金額を書き換えると自動で再計算されます。
A3: ※ 集計範囲：みずほ銀行 4〜26行／武蔵野銀行 3〜67行。行を追加する場合はこの範囲内に挿入してください。
A4: ※ 武蔵野銀行シートの74〜80行は61〜67行と同一内容の重複行のため、二重計上を避けて集計対象から除いています（同シートのE82・F82の合計式と同じ扱い）。
A5: ※ 武蔵野銀行シートの小計行（小松車輛・アスクル等の親行）はB列が空欄のため、二重計上されません。
A6: ※ みずほ銀行11行目（住友林業アーキテクノ 35,310円／ガス管破損負担分）は修繕費に含めています。
A8: ■ 合計（みずほ銀行＋武蔵野銀行）
A9: 勘定科目 | B9: ９月末 | C9: ８月末 | D9: ７月末 | E9: ６月末
A10: 通信費 | B10: =SUMIFS(みずほ銀行!C$4:C$26,みずほ銀行!$B$4:$B$26,$A10)+SUMIFS(武蔵野銀行!C$3:C$67,武蔵野銀行!$B$3:$B$67,$A10) -> 0 | C10: =SUMIFS(みずほ銀行!D$4:D$26,みずほ銀行!$B$4:$B$26,$A10)+SUMIFS(武蔵野銀行!D$3:D$67,武蔵野銀行!$B$3:$B$67,$A10) -> 84208 | D10: =SUMIFS(みずほ銀行!E$4:E$26,みずほ銀行!$B$4:$B$26,$A10)+SUMIFS(武蔵野銀行!E$3:E$67,武蔵野銀行!$B$3:$B$67,$A10) -> 82367 | E10: =SUMIFS(みずほ銀行!F$4:F$26,みずほ銀行!$B$4:$B$26,$A10)+SUMIFS(武蔵野銀行!F$3:F$67,武蔵野銀行!$B$3:$B$67,$A10) -> 72308
A11: 水道光熱費 | B11: =SUMIFS(みずほ銀行!C$4:C$26,みずほ銀行!$B$4:$B$26,$A11)+SUMIFS(武蔵野銀行!C$3:C$67,武蔵野銀行!$B$3:$B$67,$A11) -> 0 | C11: =SUMIFS(みずほ銀行!D$4:D$26,みずほ銀行!$B$4:$B$26,$A11)+SUMIFS(武蔵野銀行!D$3:D$67,武蔵野銀行!$B$3:$B$67,$A11) -> 14720 | D11: =SUMIFS(みずほ銀行!E$4:E$26,みずほ銀行!$B$4:$B$26,$A11)+SUMIFS(武蔵野銀行!E$3:E$67,武蔵野銀行!$B$3:$B$67,$A11) -> 18301 | E11: =SUMIFS(みずほ銀行!F$4:F$26,みずほ銀行!$B$4:$B$26,$A11)+SUMIFS(武蔵野銀行!F$3:F$67,武蔵野銀行!$B$3:$B$67,$A11) -> 17236
A12: 賃借料 | B12: =SUMIFS(みずほ銀行!C$4:C$26,みずほ銀行!$B$4:$B$26,$A12)+SUMIFS(武蔵野銀行!C$3:C$67,武蔵野銀行!$B$3:$B$67,$A12) -> 1794700 | C12: =SUMIFS(みずほ銀行!D$4:D$26,みずほ銀行!$B$4:$B$26,$A12)+SUMIFS(武蔵野銀行!D$3:D$67,武蔵野銀行!$B$3:$B$67,$A12) -> 2023060 | D12: =SUMIFS(みずほ銀行!E$4:E$26,みずほ銀行!$B$4:$B$26,$A12)+SUMIFS(武蔵野銀行!E$3:E$67,武蔵野銀行!$B$3:$B$67,$A12) -> 2023060 | E12: =SUMIFS(みずほ銀行!F$4:F$26,みずほ銀行!$B$4:$B$26,$A12)+SUMIFS(武蔵野銀行!F$3:F$67,武蔵野銀行!$B$3:$B$67,$A12) -> 2154895
A13: リース料 | B13: =SUMIFS(みずほ銀行!C$4:C$26,みずほ銀行!$B$4:$B$26,$A13)+SUMIFS(武蔵野銀行!C$3:C$67,武蔵野銀行!$B$3:$B$67,$A13) -> 0 | C13: =SUMIFS(みずほ銀行!D$4:D$26,みずほ銀行!$B$4:$B$26,$A13)+SUMIFS(武蔵野銀行!D$3:D$67,武蔵野銀行!$B$3:$B$67,$A13) -> 849200 | D13: =SUMIFS(みずほ銀行!E$4:E$26,みずほ銀行!$B$4:$B$26,$A13)+SUMIFS(武蔵野銀行!E$3:E$67,武蔵野銀行!$B$3:$B$67,$A13) -> 849200 | E13: =SUMIFS(みずほ銀行!F$4:F$26,みずほ銀行!$B$4:$B$26,$A13)+SUMIFS(武蔵野銀行!F$3:F$67,武蔵野銀行!$B$3:$B$67,$A13) -> 849200
A14: 修繕費 | B14: =SUMIFS(みずほ銀行!C$4:C$26,みずほ銀行!$B$4:$B$26,$A14)+SUMIFS(武蔵野銀行!C$3:C$67,武蔵野銀行!$B$3:$B$67,$A14) -> 0 | C14: =SUMIFS(みずほ銀行!D$4:D$26,みずほ銀行!$B$4:$B$26,$A14)+SUMIFS(武蔵野銀行!D$3:D$67,武蔵野銀行!$B$3:$B$67,$A14) -> 3028964 | D14: =SUMIFS(みずほ銀行!E$4:E$26,みずほ銀行!$B$4:$B$26,$A14)+SUMIFS(武蔵野銀行!E$3:E$67,武蔵野銀行!$B$3:$B$67,$A14) -> 551560 | E14: =SUMIFS(みずほ銀行!F$4:F$26,みずほ銀行!$B$4:$B$26,$A14)+SUMIFS(武蔵野銀行!F$3:F$67,武蔵野銀行!$B$3:$B$67,$A14) -> 1551552
A15: 消耗品費 | B15: =SUMIFS(みずほ銀行!C$4:C$26,みずほ銀行!$B$4:$B$26,$A15)+SUMIFS(武蔵野銀行!C$3:C$67,武蔵野銀行!$B$3:$B$67,$A15) -> 0 | C15: =SUMIFS(みずほ銀行!D$4:D$26,みずほ銀行!$B$4:$B$26,$A15)+SUMIFS(武蔵野銀行!D$3:D$67,武蔵野銀行!$B$3:$B$67,$A15) -> 943801 | D15: =SUMIFS(みずほ銀行!E$4:E$26,みずほ銀行!$B$4:$B$26,$A15)+SUMIFS(武蔵野銀行!E$3:E$67,武蔵野銀行!$B$3:$B$67,$A15) -> 1301338 | E15: =SUMIFS(みずほ銀行!F$4:F$26,みずほ銀行!$B$4:$B$26,$A15)+SUMIFS(武蔵野銀行!F$3:F$67,武蔵野銀行!$B$3:$B$67,$A15) -> 557242
A16: 消耗品費（8%） | B16: =SUMIFS(みずほ銀行!C$4:C$26,みずほ銀行!$B$4:$B$26,$A16)+SUMIFS(武蔵野銀行!C$3:C$67,武蔵野銀行!$B$3:$B$67,$A16) -> 0 | C16: =SUMIFS(みずほ銀行!D$4:D$26,みずほ銀行!$B$4:$B$26,$A16)+SUMIFS(武蔵野銀行!D$3:D$67,武蔵野銀行!$B$3:$B$67,$A16) -> 0 | D16: =SUMIFS(みずほ銀行!E$4:E$26,みずほ銀行!$B$4:$B$26,$A16)+SUMIFS(武蔵野銀行!E$3:E$67,武蔵野銀行!$B$3:$B$67,$A16) -> 66448 | E16: =SUMIFS(みずほ銀行!F$4:F$26,みずほ銀行!$B$4:$B$26,$A16)+SUMIFS(武蔵野銀行!F$3:F$67,武蔵野銀行!$B$3:$B$67,$A16) -> 0
A17: 車輛燃料費 | B17: =SUMIFS(みずほ銀行!C$4:C$26,みずほ銀行!$B$4:$B$26,$A17)+SUMIFS(武蔵野銀行!C$3:C$67,武蔵野銀行!$B$3:$B$67,$A17) -> 0 | C17: =SUMIFS(みずほ銀行!D$4:D$26,みずほ銀行!$B$4:$B$26,$A17)+SUMIFS(武蔵野銀行!D$3:D$67,武蔵野銀行!$B$3:$B$67,$A17) -> 0 | D17: =SUMIFS(みずほ銀行!E$4:E$26,みずほ銀行!$B$4:$B$26,$A17)+SUMIFS(武蔵野銀行!E$3:E$67,武蔵野銀行!$B$3:$B$67,$A17) -> 0 | E17: =SUMIFS(みずほ銀行!F$4:F$26,みずほ銀行!$B$4:$B$26,$A17)+SUMIFS(武蔵野銀行!F$3:F$67,武蔵野銀行!$B$3:$B$67,$A17) -> 0
A18: 支払手数料 | B18: =SUMIFS(みずほ銀行!C$4:C$26,みずほ銀行!$B$4:$B$26,$A18)+SUMIFS(武蔵野銀行!C$3:C$67,武蔵野銀行!$B$3:$B$67,$A18) -> 0 | C18: =SUMIFS(みずほ銀行!D$4:D$26,みずほ銀行!$B$4:$B$26,$A18)+SUMIFS(武蔵野銀行!D$3:D$67,武蔵野銀行!$B$3:$B$67,$A18) -> 8800 | D18: =SUMIFS(みずほ銀行!E$4:E$26,みずほ銀行!$B$4:$B$26,$A18)+SUMIFS(武蔵野銀行!E$3:E$67,武蔵野銀行!$B$3:$B$67,$A18) -> 23550 | E18: =SUMIFS(みずほ銀行!F$4:F$26,みずほ銀行!$B$4:$B$26,$A18)+SUMIFS(武蔵野銀行!F$3:F$67,武蔵野銀行!$B$3:$B$67,$A18) -> 0
A19: 租税公課 | B19: =SUMIFS(みずほ銀行!C$4:C$26,みずほ銀行!$B$4:$B$26,$A19)+SUMIFS(武蔵野銀行!C$3:C$67,武蔵野銀行!$B$3:$B$67,$A19) -> 0 | C19: =SUMIFS(みずほ銀行!D$4:D$26,みずほ銀行!$B$4:$B$26,$A19)+SUMIFS(武蔵野銀行!D$3:D$67,武蔵野銀行!$B$3:$B$67,$A19) -> 7500 | D19: =SUMIFS(みずほ銀行!E$4:E$26,みずほ銀行!$B$4:$B$26,$A19)+SUMIFS(武蔵野銀行!E$3:E$67,武蔵野銀行!$B$3:$B$67,$A19) -> 0 | E19: =SUMIFS(みずほ銀行!F$4:F$26,みずほ銀行!$B$4:$B$26,$A19)+SUMIFS(武蔵野銀行!F$3:F$67,武蔵野銀行!$B$3:$B$67,$A19) -> 0
A20: 保険料 | B20: =SUMIFS(みずほ銀行!C$4:C$26,みずほ銀行!$B$4:$B$26,$A20)+SUMIFS(武蔵野銀行!C$3:C$67,武蔵野銀行!$B$3:$B$67,$A20) -> 0 | C20: =SUMIFS(みずほ銀行!D$4:D$26,みずほ銀行!$B$4:$B$26,$A20)+SUMIFS(武蔵野銀行!D$3:D$67,武蔵野銀行!$B$3:$B$67,$A20) -> 17540 | D20: =SUMIFS(みずほ銀行!E$4:E$26,みずほ銀行!$B$4:$B$26,$A20)+SUMIFS(武蔵野銀行!E$3:E$67,武蔵野銀行!$B$3:$B$67,$A20) -> 22400 | E20: =SUMIFS(みずほ銀行!F$4:F$26,みずほ銀行!$B$4:$B$26,$A20)+SUMIFS(武蔵野銀行!F$3:F$67,武蔵野銀行!$B$3:$B$67,$A20) -> 0
A21: 福利厚生費 | B21: =SUMIFS(みずほ銀行!C$4:C$26,みずほ銀行!$B$4:$B$26,$A21)+SUMIFS(武蔵野銀行!C$3:C$67,武蔵野銀行!$B$3:$B$67,$A21) -> 0 | C21: =SUMIFS(みずほ銀行!D$4:D$26,みずほ銀行!$B$4:$B$26,$A21)+SUMIFS(武蔵野銀行!D$3:D$67,武蔵野銀行!$B$3:$B$67,$A21) -> 0 | D21: =SUMIFS(みずほ銀行!E$4:E$26,みずほ銀行!$B$4:$B$26,$A21)+SUMIFS(武蔵野銀行!E$3:E$67,武蔵野銀行!$B$3:$B$67,$A21) -> 0 | E21: =SUMIFS(みずほ銀行!F$4:F$26,みずほ銀行!$B$4:$B$26,$A21)+SUMIFS(武蔵野銀行!F$3:F$67,武蔵野銀行!$B$3:$B$67,$A21) -> 0
... A26: 車両運搬具 | B26: =SUMIFS(みずほ銀行!C$4:C$26,みずほ銀行!$B$4:$B$26,$A26)+SUMIFS(武蔵野銀行!C$3:C$67,武蔵野銀行!$B$3:$B$67,$A26) -> 0 | C26: =SUMIFS(みずほ銀行!D$4:D$26,みずほ銀行!$B$4:$B$26,$A26)+SUMIFS(武蔵野銀行!D$3:D$67,武蔵野銀行!$B$3:$B$67,$A26) -> 0 | D26: =SUMIFS(みずほ銀行!E$4:E$26,みずほ銀行!$B$4:$B$26,$A26)+SUMIFS(武蔵野銀行!E$3:E$67,武蔵野銀行!$B$3:$B$67,$A26) -> 0 | E26: =SUMIFS(みずほ銀行!F$4:F$26,みずほ銀行!$B$4:$B$26,$A26)+SUMIFS(武蔵野銀行!F$3:F$67,武蔵野銀行!$B$3:$B$67,$A26) -> 0
A27: 合計 | B27: =SUM(B10:B26) -> 1854700 | C27: =SUM(C10:C26) -> 7721672 | D27: =SUM(D10:D26) -> 6548661 | E27: =SUM(E10:E26) -> 5436993
A30: ■ みずほ銀行
A31: 勘定科目 | B31: ９月末 | C31: ８月末 | D31: ７月末 | E31: ６月末
A32: 通信費 | B32: =SUMIFS(みずほ銀行!C$4:C$26,みずほ銀行!$B$4:$B$26,$A32) -> 0 | C32: =SUMIFS(みずほ銀行!D$4:D$26,みずほ銀行!$B$4:$B$26,$A32) -> 84208 | D32: =SUMIFS(みずほ銀行!E$4:E$26,みずほ銀行!$B$4:$B$26,$A32) -> 82367 | E32: =SUMIFS(みずほ銀行!F$4:F$26,みずほ銀行!$B$4:$B$26,$A32) -> 72308
A33: 水道光熱費 | B33: =SUMIFS(みずほ銀行!C$4:C$26,みずほ銀行!$B$4:$B$26,$A33) -> 0 | C33: =SUMIFS(みずほ銀行!D$4:D$26,みずほ銀行!$B$4:$B$26,$A33) -> 14720 | D33: =SUMIFS(みずほ銀行!E$4:E$26,みずほ銀行!$B$4:$B$26,$A33) -> 18301 | E33: =SUMIFS(みずほ銀行!F$4:F$26,みずほ銀行!$B$4:$B$26,$A33) -> 17236
A34: 賃借料 | B34: =SUMIFS(みずほ銀行!C$4:C$26,みずほ銀行!$B$4:$B$26,$A34) -> 1794700 | C34: =SUMIFS(みずほ銀行!D$4:D$26,みずほ銀行!$B$4:$B$26,$A34) -> 1580860 | D34: =SUMIFS(みずほ銀行!E$4:E$26,みずほ銀行!$B$4:$B$26,$A34) -> 1580860 | E34: =SUMIFS(みずほ銀行!F$4:F$26,みずほ銀行!$B$4:$B$26,$A34) -> 1712695
A35: リース料 | B35: =SUMIFS(みずほ銀行!C$4:C$26,みずほ銀行!$B$4:$B$26,$A35) -> 0 | C35: =SUMIFS(みずほ銀行!D$4:D$26,みずほ銀行!$B$4:$B$26,$A35) -> 0 | D35: =SUMIFS(みずほ銀行!E$4:E$26,みずほ銀行!$B$4:$B$26,$A35) -> 0 | E35: =SUMIFS(みずほ銀行!F$4:F$26,みずほ銀行!$B$4:$B$26,$A35) -> 0
A36: 修繕費 | B36: =SUMIFS(みずほ銀行!C$4:C$26,みずほ銀行!$B$4:$B$26,$A36) -> 0 | C36: =SUMIFS(みずほ銀行!D$4:D$26,みずほ銀行!$B$4:$B$26,$A36) -> 35310 | D36: =SUMIFS(みずほ銀行!E$4:E$26,みずほ銀行!$B$4:$B$26,$A36) -> 0 | E36: =SUMIFS(みずほ銀行!F$4:F$26,みずほ銀行!$B$4:$B$26,$A36) -> 0
A37: 消耗品費 | B37: =SUMIFS(みずほ銀行!C$4:C$26,みずほ銀行!$B$4:$B$26,$A37) -> 0 | C37: =SUMIFS(みずほ銀行!D$4:D$26,みずほ銀行!$B$4:$B$26,$A37) -> 160084 | D37: =SUMIFS(みずほ銀行!E$4:E$26,みずほ銀行!$B$4:$B$26,$A37) -> 102568 | E37: =SUMIFS(みずほ銀行!F$4:F$26,みずほ銀行!$B$4:$B$26,$A37) -> 93408
A38: 消耗品費（8%） | B38: =SUMIFS(みずほ銀行!C$4:C$26,みずほ銀行!$B$4:$B$26,$A38) -> 0 | C38: =SUMIFS(みずほ銀行!D$4:D$26,みずほ銀行!$B$4:$B$26,$A38) -> 0 | D38: =SUMIFS(みずほ銀行!E$4:E$26,みずほ銀行!$B$4:$B$26,$A38) -> 66448 | E38: =SUMIFS(みずほ銀行!F$4:F$26,みずほ銀行!$B$4:$B$26,$A38) -> 0
A39: 車輛燃料費 | B39: =SUMIFS(みずほ銀行!C$4:C$26,みずほ銀行!$B$4:$B$26,$A39) -> 0 | C39: =SUMIFS(みずほ銀行!D$4:D$26,みずほ銀行!$B$4:$B$26,$A39) -> 0 | D39: =SUMIFS(みずほ銀行!E$4:E$26,みずほ銀行!$B$4:$B$26,$A39) -> 0 | E39: =SUMIFS(みずほ銀行!F$4:F$26,みずほ銀行!$B$4:$B$26,$A39) -> 0
A40: 支払手数料 | B40: =SUMIFS(みずほ銀行!C$4:C$26,みずほ銀行!$B$4:$B$26,$A40) -> 0 | C40: =SUMIFS(みずほ銀行!D$4:D$26,みずほ銀行!$B$4:$B$26,$A40) -> 0 | D40: =SUMIFS(みずほ銀行!E$4:E$26,みずほ銀行!$B$4:$B$26,$A40) -> 0 | E40: =SUMIFS(みずほ銀行!F$4:F$26,みずほ銀行!$B$4:$B$26,$A40) -> 0
A41: 租税公課 | B41: =SUMIFS(みずほ銀行!C$4:C$26,みずほ銀行!$B$4:$B$26,$A41) -> 0 | C41: =SUMIFS(みずほ銀行!D$4:D$26,みずほ銀行!$B$4:$B$26,$A41) -> 0 | D41: =SUMIFS(みずほ銀行!E$4:E$26,みずほ銀行!$B$4:$B$26,$A41) -> 0 | E41: =SUMIFS(みずほ銀行!F$4:F$26,みずほ銀行!$B$4:$B$26,$A41) -> 0
A42: 保険料 | B42: =SUMIFS(みずほ銀行!C$4:C$26,みずほ銀行!$B$4:$B$26,$A42) -> 0 | C42: =SUMIFS(みずほ銀行!D$4:D$26,みずほ銀行!$B$4:$B$26,$A42) -> 0 | D42: =SUMIFS(みずほ銀行!E$4:E$26,みずほ銀行!$B$4:$B$26,$A42) -> 0 | E42: =SUMIFS(みずほ銀行!F$4:F$26,みずほ銀行!$B$4:$B$26,$A42) -> 0
A43: 福利厚生費 | B43: =SUMIFS(みずほ銀行!C$4:C$26,みずほ銀行!$B$4:$B$26,$A43) -> 0 | C43: =SUMIFS(みずほ銀行!D$4:D$26,みずほ銀行!$B$4:$B$26,$A43) -> 0 | D43: =SUMIFS(みずほ銀行!E$4:E$26,みずほ銀行!$B$4:$B$26,$A43) -> 0 | E43: =SUMIFS(みずほ銀行!F$4:F$26,みずほ銀行!$B$4:$B$26,$A43) -> 0
... A48: 車両運搬具 | B48: =SUMIFS(みずほ銀行!C$4:C$26,みずほ銀行!$B$4:$B$26,$A48) -> 0 | C48: =SUMIFS(みずほ銀行!D$4:D$26,みずほ銀行!$B$4:$B$26,$A48) -> 0 | D48: =SUMIFS(みずほ銀行!E$4:E$26,みずほ銀行!$B$4:$B$26,$A48) -> 0 | E48: =SUMIFS(みずほ銀行!F$4:F$26,みずほ銀行!$B$4:$B$26,$A48) -> 0
A49: 合計 | B49: =SUM(B32:B48) -> 1854700 | C49: =SUM(C32:C48) -> 1875182 | D49: =SUM(D32:D48) -> 1850544 | E49: =SUM(E32:E48) -> 1895647
A52: ■ 武蔵野銀行
A53: 勘定科目 | B53: ９月末 | C53: ８月末 | D53: ７月末 | E53: ６月末
...
