Workbook

Sheet 月次一覧
A1: 事務所別 月次支払一覧 | C1: ※ 金額は各事務所シートへの参照です。元シートを直すとこの表も変わります。
A3: 支払日 | B3: 振込額（支払額） | F3: 請求額（税込み） | J3: 源泉徴収額
B4: 井坂事務所 | C4: 岡崎事務所 | D4: 綾測 | E4: 合計 | F4: 井坂事務所 | G4: 岡崎事務所 | H4: 綾測 | I4: 合計 | J4: 井坂事務所 | K4: 岡崎事務所 | L4: 綾測 | M4: 合計
A5: ='井坂事務所'!A2 | B5: =IF(N('井坂事務所'!F2)=0,"",'井坂事務所'!F2) | C5: =IF(N('岡崎事務所'!F2)=0,"",'岡崎事務所'!F2) | D5: =IF(N('綾測'!F2)=0,"",'綾測'!F2) | E5: =IF(SUM(B5:D5)=0,"",SUM(B5:D5)) | F5: =IF(N('井坂事務所'!D2)=0,"",'井坂事務所'!D2) | G5: =IF(N('岡崎事務所'!D2)=0,"",'岡崎事務所'!D2) | H5: =IF(N('綾測'!D2)=0,"",'綾測'!D2) | I5: =IF(SUM(F5:H5)=0,"",SUM(F5:H5)) | J5: =IF(N('井坂事務所'!E2)=0,"",'井坂事務所'!E2) | K5: =IF(N('岡崎事務所'!E2)=0,"",'岡崎事務所'!E2) | L5: =IF(N('綾測'!E2)=0,"",'綾測'!E2) | M5: =IF(SUM(J5:L5)=0,"",SUM(J5:L5))
A6: ='井坂事務所'!A3 | B6: =IF(N('井坂事務所'!F3)=0,"",'井坂事務所'!F3) | C6: =IF(N('岡崎事務所'!F3)=0,"",'岡崎事務所'!F3) | D6: =IF(N('綾測'!F3)=0,"",'綾測'!F3) | E6: =IF(SUM(B6:D6)=0,"",SUM(B6:D6)) | F6: =IF(N('井坂事務所'!D3)=0,"",'井坂事務所'!D3) | G6: =IF(N('岡崎事務所'!D3)=0,"",'岡崎事務所'!D3) | H6: =IF(N('綾測'!D3)=0,"",'綾測'!D3) | I6: =IF(SUM(F6:H6)=0,"",SUM(F6:H6)) | J6: =IF(N('井坂事務所'!E3)=0,"",'井坂事務所'!E3) | K6: =IF(N('岡崎事務所'!E3)=0,"",'岡崎事務所'!E3) | L6: =IF(N('綾測'!E3)=0,"",'綾測'!E3) | M6: =IF(SUM(J6:L6)=0,"",SUM(J6:L6))
A7: ='井坂事務所'!A4 | B7: =IF(N('井坂事務所'!F4)=0,"",'井坂事務所'!F4) | C7: =IF(N('岡崎事務所'!F4)=0,"",'岡崎事務所'!F4) | D7: =IF(N('綾測'!F4)=0,"",'綾測'!F4) | E7: =IF(SUM(B7:D7)=0,"",SUM(B7:D7)) | F7: =IF(N('井坂事務所'!D4)=0,"",'井坂事務所'!D4) | G7: =IF(N('岡崎事務所'!D4)=0,"",'岡崎事務所'!D4) | H7: =IF(N('綾測'!D4)=0,"",'綾測'!D4) | I7: =IF(SUM(F7:H7)=0,"",SUM(F7:H7)) | J7: =IF(N('井坂事務所'!E4)=0,"",'井坂事務所'!E4) | K7: =IF(N('岡崎事務所'!E4)=0,"",'岡崎事務所'!E4) | L7: =IF(N('綾測'!E4)=0,"",'綾測'!E4) | M7: =IF(SUM(J7:L7)=0,"",SUM(J7:L7))
A8: ='井坂事務所'!A5 | B8: =IF(N('井坂事務所'!F5)=0,"",'井坂事務所'!F5) | C8: =IF(N('岡崎事務所'!F5)=0,"",'岡崎事務所'!F5) | D8: =IF(N('綾測'!F5)=0,"",'綾測'!F5) | E8: =IF(SUM(B8:D8)=0,"",SUM(B8:D8)) | F8: =IF(N('井坂事務所'!D5)=0,"",'井坂事務所'!D5) | G8: =IF(N('岡崎事務所'!D5)=0,"",'岡崎事務所'!D5) | H8: =IF(N('綾測'!D5)=0,"",'綾測'!D5) | I8: =IF(SUM(F8:H8)=0,"",SUM(F8:H8)) | J8: =IF(N('井坂事務所'!E5)=0,"",'井坂事務所'!E5) | K8: =IF(N('岡崎事務所'!E5)=0,"",'岡崎事務所'!E5) | L8: =IF(N('綾測'!E5)=0,"",'綾測'!E5) | M8: =IF(SUM(J8:L8)=0,"",SUM(J8:L8))
A9: ='井坂事務所'!A6 | B9: =IF(N('井坂事務所'!F6)=0,"",'井坂事務所'!F6) | C9: =IF(N('岡崎事務所'!F6)=0,"",'岡崎事務所'!F6) | D9: =IF(N('綾測'!F6)=0,"",'綾測'!F6) | E9: =IF(SUM(B9:D9)=0,"",SUM(B9:D9)) | F9: =IF(N('井坂事務所'!D6)=0,"",'井坂事務所'!D6) | G9: =IF(N('岡崎事務所'!D6)=0,"",'岡崎事務所'!D6) | H9: =IF(N('綾測'!D6)=0,"",'綾測'!D6) | I9: =IF(SUM(F9:H9)=0,"",SUM(F9:H9)) | J9: =IF(N('井坂事務所'!E6)=0,"",'井坂事務所'!E6) | K9: =IF(N('岡崎事務所'!E6)=0,"",'岡崎事務所'!E6) | L9: =IF(N('綾測'!E6)=0,"",'綾測'!E6) | M9: =IF(SUM(J9:L9)=0,"",SUM(J9:L9))
A10: ='井坂事務所'!A7 | B10: =IF(N('井坂事務所'!F7)=0,"",'井坂事務所'!F7) | C10: =IF(N('岡崎事務所'!F7)=0,"",'岡崎事務所'!F7) | D10: =IF(N('綾測'!F7)=0,"",'綾測'!F7) | E10: =IF(SUM(B10:D10)=0,"",SUM(B10:D10)) | F10: =IF(N('井坂事務所'!D7)=0,"",'井坂事務所'!D7) | G10: =IF(N('岡崎事務所'!D7)=0,"",'岡崎事務所'!D7) | H10: =IF(N('綾測'!D7)=0,"",'綾測'!D7) | I10: =IF(SUM(F10:H10)=0,"",SUM(F10:H10)) | J10: =IF(N('井坂事務所'!E7)=0,"",'井坂事務所'!E7) | K10: =IF(N('岡崎事務所'!E7)=0,"",'岡崎事務所'!E7) | L10: =IF(N('綾測'!E7)=0,"",'綾測'!E7) | M10: =IF(SUM(J10:L10)=0,"",SUM(J10:L10))
A11: ='井坂事務所'!A8 | B11: =IF(N('井坂事務所'!F8)=0,"",'井坂事務所'!F8) | C11: =IF(N('岡崎事務所'!F8)=0,"",'岡崎事務所'!F8) | D11: =IF(N('綾測'!F8)=0,"",'綾測'!F8) | E11: =IF(SUM(B11:D11)=0,"",SUM(B11:D11)) | F11: =IF(N('井坂事務所'!D8)=0,"",'井坂事務所'!D8) | G11: =IF(N('岡崎事務所'!D8)=0,"",'岡崎事務所'!D8) | H11: =IF(N('綾測'!D8)=0,"",'綾測'!D8) | I11: =IF(SUM(F11:H11)=0,"",SUM(F11:H11)) | J11: =IF(N('井坂事務所'!E8)=0,"",'井坂事務所'!E8) | K11: =IF(N('岡崎事務所'!E8)=0,"",'岡崎事務所'!E8) | L11: =IF(N('綾測'!E8)=0,"",'綾測'!E8) | M11: =IF(SUM(J11:L11)=0,"",SUM(J11:L11))
A12: ='井坂事務所'!A9 | B12: =IF(N('井坂事務所'!F9)=0,"",'井坂事務所'!F9) | C12: =IF(N('岡崎事務所'!F9)=0,"",'岡崎事務所'!F9) | D12: =IF(N('綾測'!F9)=0,"",'綾測'!F9) | E12: =IF(SUM(B12:D12)=0,"",SUM(B12:D12)) | F12: =IF(N('井坂事務所'!D9)=0,"",'井坂事務所'!D9) | G12: =IF(N('岡崎事務所'!D9)=0,"",'岡崎事務所'!D9) | H12: =IF(N('綾測'!D9)=0,"",'綾測'!D9) | I12: =IF(SUM(F12:H12)=0,"",SUM(F12:H12)) | J12: =IF(N('井坂事務所'!E9)=0,"",'井坂事務所'!E9) | K12: =IF(N('岡崎事務所'!E9)=0,"",'岡崎事務所'!E9) | L12: =IF(N('綾測'!E9)=0,"",'綾測'!E9) | M12: =IF(SUM(J12:L12)=0,"",SUM(J12:L12))
A13: ='井坂事務所'!A10 | B13: =IF(N('井坂事務所'!F10)=0,"",'井坂事務所'!F10) | C13: =IF(N('岡崎事務所'!F10)=0,"",'岡崎事務所'!F10) | D13: =IF(N('綾測'!F10)=0,"",'綾測'!F10) | E13: =IF(SUM(B13:D13)=0,"",SUM(B13:D13)) | F13: =IF(N('井坂事務所'!D10)=0,"",'井坂事務所'!D10) | G13: =IF(N('岡崎事務所'!D10)=0,"",'岡崎事務所'!D10) | H13: =IF(N('綾測'!D10)=0,"",'綾測'!D10) | I13: =IF(SUM(F13:H13)=0,"",SUM(F13:H13)) | J13: =IF(N('井坂事務所'!E10)=0,"",'井坂事務所'!E10) | K13: =IF(N('岡崎事務所'!E10)=0,"",'岡崎事務所'!E10) | L13: =IF(N('綾測'!E10)=0,"",'綾測'!E10) | M13: =IF(SUM(J13:L13)=0,"",SUM(J13:L13))
A14: ='井坂事務所'!A11 | B14: =IF(N('井坂事務所'!F11)=0,"",'井坂事務所'!F11) | C14: =IF(N('岡崎事務所'!F11)=0,"",'岡崎事務所'!F11) | D14: =IF(N('綾測'!F11)=0,"",'綾測'!F11) | E14: =IF(SUM(B14:D14)=0,"",SUM(B14:D14)) | F14: =IF(N('井坂事務所'!D11)=0,"",'井坂事務所'!D11) | G14: =IF(N('岡崎事務所'!D11)=0,"",'岡崎事務所'!D11) | H14: =IF(N('綾測'!D11)=0,"",'綾測'!D11) | I14: =IF(SUM(F14:H14)=0,"",SUM(F14:H14)) | J14: =IF(N('井坂事務所'!E11)=0,"",'井坂事務所'!E11) | K14: =IF(N('岡崎事務所'!E11)=0,"",'岡崎事務所'!E11) | L14: =IF(N('綾測'!E11)=0,"",'綾測'!E11) | M14: =IF(SUM(J14:L14)=0,"",SUM(J14:L14))
A15: ='井坂事務所'!A12 | B15: =IF(N('井坂事務所'!F12)=0,"",'井坂事務所'!F12) | C15: =IF(N('岡崎事務所'!F12)=0,"",'岡崎事務所'!F12) | D15: =IF(N('綾測'!F12)=0,"",'綾測'!F12) | E15: =IF(SUM(B15:D15)=0,"",SUM(B15:D15)) | F15: =IF(N('井坂事務所'!D12)=0,"",'井坂事務所'!D12) | G15: =IF(N('岡崎事務所'!D12)=0,"",'岡崎事務所'!D12) | H15: =IF(N('綾測'!D12)=0,"",'綾測'!D12) | I15: =IF(SUM(F15:H15)=0,"",SUM(F15:H15)) | J15: =IF(N('井坂事務所'!E12)=0,"",'井坂事務所'!E12) | K15: =IF(N('岡崎事務所'!E12)=0,"",'岡崎事務所'!E12) | L15: =IF(N('綾測'!E12)=0,"",'綾測'!E12) | M15: =IF(SUM(J15:L15)=0,"",SUM(J15:L15))
A16: ='井坂事務所'!A13 | B16: =IF(N('井坂事務所'!F13)=0,"",'井坂事務所'!F13) | C16: =IF(N('岡崎事務所'!F13)=0,"",'岡崎事務所'!F13) | D16: =IF(N('綾測'!F13)=0,"",'綾測'!F13) | E16: =IF(SUM(B16:D16)=0,"",SUM(B16:D16)) | F16: =IF(N('井坂事務所'!D13)=0,"",'井坂事務所'!D13) | G16: =IF(N('岡崎事務所'!D13)=0,"",'岡崎事務所'!D13) | H16: =IF(N('綾測'!D13)=0,"",'綾測'!D13) | I16: =IF(SUM(F16:H16)=0,"",SUM(F16:H16)) | J16: =IF(N('井坂事務所'!E13)=0,"",'井坂事務所'!E13) | K16: =IF(N('岡崎事務所'!E13)=0,"",'岡崎事務所'!E13) | L16: =IF(N('綾測'!E13)=0,"",'綾測'!E13) | M16: =IF(SUM(J16:L16)=0,"",SUM(J16:L16))
A17: 2026年 計 | B17: =IF(SUM(B5:B16)=0,"",SUM(B5:B16)) | C17: =IF(SUM(C5:C16)=0,"",SUM(C5:C16)) | D17: =IF(SUM(D5:D16)=0,"",SUM(D5:D16)) | E17: =IF(SUM(E5:E16)=0,"",SUM(E5:E16)) | F17: =IF(SUM(F5:F16)=0,"",SUM(F5:F16)) | G17: =IF(SUM(G5:G16)=0,"",SUM(G5:G16)) | H17: =IF(SUM(H5:H16)=0,"",SUM(H5:H16)) | I17: =IF(SUM(I5:I16)=0,"",SUM(I5:I16)) | ... M17: =IF(SUM(M5:M16)=0,"",SUM(M5:M16))
A18: ='井坂事務所'!A14 | B18: =IF(N('井坂事務所'!F14)=0,"",'井坂事務所'!F14) | C18: =IF(N('岡崎事務所'!F14)=0,"",'岡崎事務所'!F14) | D18: =IF(N('綾測'!F14)=0,"",'綾測'!F14) | E18: =IF(SUM(B18:D18)=0,"",SUM(B18:D18)) | F18: =IF(N('井坂事務所'!D14)=0,"",'井坂事務所'!D14) | G18: =IF(N('岡崎事務所'!D14)=0,"",'岡崎事務所'!D14) | H18: =IF(N('綾測'!D14)=0,"",'綾測'!D14) | I18: =IF(SUM(F18:H18)=0,"",SUM(F18:H18)) | J18: =IF(N('井坂事務所'!E14)=0,"",'井坂事務所'!E14) | K18: =IF(N('岡崎事務所'!E14)=0,"",'岡崎事務所'!E14) | L18: =IF(N('綾測'!E14)=0,"",'綾測'!E14) | M18: =IF(SUM(J18:L18)=0,"",SUM(J18:L18))
A19: ='井坂事務所'!A15 | B19: =IF(N('井坂事務所'!F15)=0,"",'井坂事務所'!F15) | C19: =IF(N('岡崎事務所'!F15)=0,"",'岡崎事務所'!F15) | D19: =IF(N('綾測'!F15)=0,"",'綾測'!F15) | E19: =IF(SUM(B19:D19)=0,"",SUM(B19:D19)) | F19: =IF(N('井坂事務所'!D15)=0,"",'井坂事務所'!D15) | G19: =IF(N('岡崎事務所'!D15)=0,"",'岡崎事務所'!D15) | H19: =IF(N('綾測'!D15)=0,"",'綾測'!D15) | I19: =IF(SUM(F19:H19)=0,"",SUM(F19:H19)) | J19: =IF(N('井坂事務所'!E15)=0,"",'井坂事務所'!E15) | K19: =IF(N('岡崎事務所'!E15)=0,"",'岡崎事務所'!E15) | L19: =IF(N('綾測'!E15)=0,"",'綾測'!E15) | M19: =IF(SUM(J19:L19)=0,"",SUM(J19:L19))
A20: ='井坂事務所'!A16 | B20: =IF(N('井坂事務所'!F16)=0,"",'井坂事務所'!F16) | C20: =IF(N('岡崎事務所'!F16)=0,"",'岡崎事務所'!F16) | D20: =IF(N('綾測'!F16)=0,"",'綾測'!F16) | E20: =IF(SUM(B20:D20)=0,"",SUM(B20:D20)) | F20: =IF(N('井坂事務所'!D16)=0,"",'井坂事務所'!D16) | G20: =IF(N('岡崎事務所'!D16)=0,"",'岡崎事務所'!D16) | H20: =IF(N('綾測'!D16)=0,"",'綾測'!D16) | I20: =IF(SUM(F20:H20)=0,"",SUM(F20:H20)) | J20: =IF(N('井坂事務所'!E16)=0,"",'井坂事務所'!E16) | K20: =IF(N('岡崎事務所'!E16)=0,"",'岡崎事務所'!E16) | L20: =IF(N('綾測'!E16)=0,"",'綾測'!E16) | M20: =IF(SUM(J20:L20)=0,"",SUM(J20:L20))
A21: ='井坂事務所'!A17 | B21: =IF(N('井坂事務所'!F17)=0,"",'井坂事務所'!F17) | C21: =IF(N('岡崎事務所'!F17)=0,"",'岡崎事務所'!F17) | D21: =IF(N('綾測'!F17)=0,"",'綾測'!F17) | E21: =IF(SUM(B21:D21)=0,"",SUM(B21:D21)) | F21: =IF(N('井坂事務所'!D17)=0,"",'井坂事務所'!D17) | G21: =IF(N('岡崎事務所'!D17)=0,"",'岡崎事務所'!D17) | H21: =IF(N('綾測'!D17)=0,"",'綾測'!D17) | I21: =IF(SUM(F21:H21)=0,"",SUM(F21:H21)) | J21: =IF(N('井坂事務所'!E17)=0,"",'井坂事務所'!E17) | K21: =IF(N('岡崎事務所'!E17)=0,"",'岡崎事務所'!E17) | L21: =IF(N('綾測'!E17)=0,"",'綾測'!E17) | M21: =IF(SUM(J21:L21)=0,"",SUM(J21:L21))
A22: ='井坂事務所'!A18 | B22: =IF(N('井坂事務所'!F18)=0,"",'井坂事務所'!F18) | C22: =IF(N('岡崎事務所'!F18)=0,"",'岡崎事務所'!F18) | D22: =IF(N('綾測'!F18)=0,"",'綾測'!F18) | E22: =IF(SUM(B22:D22)=0,"",SUM(B22:D22)) | F22: =IF(N('井坂事務所'!D18)=0,"",'井坂事務所'!D18) | G22: =IF(N('岡崎事務所'!D18)=0,"",'岡崎事務所'!D18) | H22: =IF(N('綾測'!D18)=0,"",'綾測'!D18) | I22: =IF(SUM(F22:H22)=0,"",SUM(F22:H22)) | J22: =IF(N('井坂事務所'!E18)=0,"",'井坂事務所'!E18) | K22: =IF(N('岡崎事務所'!E18)=0,"",'岡崎事務所'!E18) | L22: =IF(N('綾測'!E18)=0,"",'綾測'!E18) | M22: =IF(SUM(J22:L22)=0,"",SUM(J22:L22))
A23: ='井坂事務所'!A19 | B23: =IF(N('井坂事務所'!F19)=0,"",'井坂事務所'!F19) | C23: =IF(N('岡崎事務所'!F19)=0,"",'岡崎事務所'!F19) | D23: =IF(N('綾測'!F19)=0,"",'綾測'!F19) | E23: =IF(SUM(B23:D23)=0,"",SUM(B23:D23)) | F23: =IF(N('井坂事務所'!D19)=0,"",'井坂事務所'!D19) | G23: =IF(N('岡崎事務所'!D19)=0,"",'岡崎事務所'!D19) | H23: =IF(N('綾測'!D19)=0,"",'綾測'!D19) | I23: =IF(SUM(F23:H23)=0,"",SUM(F23:H23)) | J23: =IF(N('井坂事務所'!E19)=0,"",'井坂事務所'!E19) | K23: =IF(N('岡崎事務所'!E19)=0,"",'岡崎事務所'!E19) | L23: =IF(N('綾測'!E19)=0,"",'綾測'!E19) | M23: =IF(SUM(J23:L23)=0,"",SUM(J23:L23))
A24: ='井坂事務所'!A20 | B24: =IF(N('井坂事務所'!F20)=0,"",'井坂事務所'!F20) | C24: =IF(N('岡崎事務所'!F20)=0,"",'岡崎事務所'!F20) | D24: =IF(N('綾測'!F20)=0,"",'綾測'!F20) | E24: =IF(SUM(B24:D24)=0,"",SUM(B24:D24)) | F24: =IF(N('井坂事務所'!D20)=0,"",'井坂事務所'!D20) | G24: =IF(N('岡崎事務所'!D20)=0,"",'岡崎事務所'!D20) | H24: =IF(N('綾測'!D20)=0,"",'綾測'!D20) | I24: =IF(SUM(F24:H24)=0,"",SUM(F24:H24)) | J24: =IF(N('井坂事務所'!E20)=0,"",'井坂事務所'!E20) | K24: =IF(N('岡崎事務所'!E20)=0,"",'岡崎事務所'!E20) | L24: =IF(N('綾測'!E20)=0,"",'綾測'!E20) | M24: =IF(SUM(J24:L24)=0,"",SUM(J24:L24))
A25: ='井坂事務所'!A21 | B25: =IF(N('井坂事務所'!F21)=0,"",'井坂事務所'!F21) | C25: =IF(N('岡崎事務所'!F21)=0,"",'岡崎事務所'!F21) | D25: =IF(N('綾測'!F21)=0,"",'綾測'!F21) | E25: =IF(SUM(B25:D25)=0,"",SUM(B25:D25)) | F25: =IF(N('井坂事務所'!D21)=0,"",'井坂事務所'!D21) | G25: =IF(N('岡崎事務所'!D21)=0,"",'岡崎事務所'!D21) | H25: =IF(N('綾測'!D21)=0,"",'綾測'!D21) | I25: =IF(SUM(F25:H25)=0,"",SUM(F25:H25)) | J25: =IF(N('井坂事務所'!E21)=0,"",'井坂事務所'!E21) | K25: =IF(N('岡崎事務所'!E21)=0,"",'岡崎事務所'!E21) | L25: =IF(N('綾測'!E21)=0,"",'綾測'!E21) | M25: =IF(SUM(J25:L25)=0,"",SUM(J25:L25))
A26: ='井坂事務所'!A22 | B26: =IF(N('井坂事務所'!F22)=0,"",'井坂事務所'!F22) | C26: =IF(N('岡崎事務所'!F22)=0,"",'岡崎事務所'!F22) | D26: =IF(N('綾測'!F22)=0,"",'綾測'!F22) | E26: =IF(SUM(B26:D26)=0,"",SUM(B26:D26)) | F26: =IF(N('井坂事務所'!D22)=0,"",'井坂事務所'!D22) | G26: =IF(N('岡崎事務所'!D22)=0,"",'岡崎事務所'!D22) | H26: =IF(N('綾測'!D22)=0,"",'綾測'!D22) | I26: =IF(SUM(F26:H26)=0,"",SUM(F26:H26)) | J26: =IF(N('井坂事務所'!E22)=0,"",'井坂事務所'!E22) | K26: =IF(N('岡崎事務所'!E22)=0,"",'岡崎事務所'!E22) | L26: =IF(N('綾測'!E22)=0,"",'綾測'!E22) | M26: =IF(SUM(J26:L26)=0,"",SUM(J26:L26))
A27: ='井坂事務所'!A23 | B27: =IF(N('井坂事務所'!F23)=0,"",'井坂事務所'!F23) | C27: =IF(N('岡崎事務所'!F23)=0,"",'岡崎事務所'!F23) | D27: =IF(N('綾測'!F23)=0,"",'綾測'!F23) | E27: =IF(SUM(B27:D27)=0,"",SUM(B27:D27)) | F27: =IF(N('井坂事務所'!D23)=0,"",'井坂事務所'!D23) | G27: =IF(N('岡崎事務所'!D23)=0,"",'岡崎事務所'!D23) | H27: =IF(N('綾測'!D23)=0,"",'綾測'!D23) | I27: =IF(SUM(F27:H27)=0,"",SUM(F27:H27)) | J27: =IF(N('井坂事務所'!E23)=0,"",'井坂事務所'!E23) | K27: =IF(N('岡崎事務所'!E23)=0,"",'岡崎事務所'!E23) | L27: =IF(N('綾測'!E23)=0,"",'綾測'!E23) | M27: =IF(SUM(J27:L27)=0,"",SUM(J27:L27))
A28: ='井坂事務所'!A24 | B28: =IF(N('井坂事務所'!F24)=0,"",'井坂事務所'!F24) | C28: =IF(N('岡崎事務所'!F24)=0,"",'岡崎事務所'!F24) | D28: =IF(N('綾測'!F24)=0,"",'綾測'!F24) | E28: =IF(SUM(B28:D28)=0,"",SUM(B28:D28)) | F28: =IF(N('井坂事務所'!D24)=0,"",'井坂事務所'!D24) | G28: =IF(N('岡崎事務所'!D24)=0,"",'岡崎事務所'!D24) | H28: =IF(N('綾測'!D24)=0,"",'綾測'!D24) | I28: =IF(SUM(F28:H28)=0,"",SUM(F28:H28)) | J28: =IF(N('井坂事務所'!E24)=0,"",'井坂事務所'!E24) | K28: =IF(N('岡崎事務所'!E24)=0,"",'岡崎事務所'!E24) | L28: =IF(N('綾測'!E24)=0,"",'綾測'!E24) | M28: =IF(SUM(J28:L28)=0,"",SUM(J28:L28))
A29: ='井坂事務所'!A25 | B29: =IF(N('井坂事務所'!F25)=0,"",'井坂事務所'!F25) | C29: =IF(N('岡崎事務所'!F25)=0,"",'岡崎事務所'!F25) | D29: =IF(N('綾測'!F25)=0,"",'綾測'!F25) | E29: =IF(SUM(B29:D29)=0,"",SUM(B29:D29)) | F29: =IF(N('井坂事務所'!D25)=0,"",'井坂事務所'!D25) | G29: =IF(N('岡崎事務所'!D25)=0,"",'岡崎事務所'!D25) | H29: =IF(N('綾測'!D25)=0,"",'綾測'!D25) | I29: =IF(SUM(F29:H29)=0,"",SUM(F29:H29)) | J29: =IF(N('井坂事務所'!E25)=0,"",'井坂事務所'!E25) | K29: =IF(N('岡崎事務所'!E25)=0,"",'岡崎事務所'!E25) | L29: =IF(N('綾測'!E25)=0,"",'綾測'!E25) | M29: =IF(SUM(J29:L29)=0,"",SUM(J29:L29))
A30: 2027年 計 | B30: =IF(SUM(B18:B29)=0,"",SUM(B18:B29)) | C30: =IF(SUM(C18:C29)=0,"",SUM(C18:C29)) | D30: =IF(SUM(D18:D29)=0,"",SUM(D18:D29)) | E30: =IF(SUM(E18:E29)=0,"",SUM(E18:E29)) | F30: =IF(SUM(F18:F29)=0,"",SUM(F18:F29)) | G30: =IF(SUM(G18:G29)=0,"",SUM(G18:G29)) | H30: =IF(SUM(H18:H29)=0,"",SUM(H18:H29)) | I30: =IF(SUM(I18:I29)=0,"",SUM(I18:I29)) | ... M30: =IF(SUM(M18:M29)=0,"",SUM(M18:M29))
A31: ='井坂事務所'!A26 | B31: =IF(N('井坂事務所'!F26)=0,"",'井坂事務所'!F26) | C31: =IF(N('岡崎事務所'!F26)=0,"",'岡崎事務所'!F26) | D31: =IF(N('綾測'!F26)=0,"",'綾測'!F26) | E31: =IF(SUM(B31:D31)=0,"",SUM(B31:D31)) | F31: =IF(N('井坂事務所'!D26)=0,"",'井坂事務所'!D26) | G31: =IF(N('岡崎事務所'!D26)=0,"",'岡崎事務所'!D26) | H31: =IF(N('綾測'!D26)=0,"",'綾測'!D26) | I31: =IF(SUM(F31:H31)=0,"",SUM(F31:H31)) | J31: =IF(N('井坂事務所'!E26)=0,"",'井坂事務所'!E26) | K31: =IF(N('岡崎事務所'!E26)=0,"",'岡崎事務所'!E26) | L31: =IF(N('綾測'!E26)=0,"",'綾測'!E26) | M31: =IF(SUM(J31:L31)=0,"",SUM(J31:L31))
A32: ='井坂事務所'!A27 | B32: =IF(N('井坂事務所'!F27)=0,"",'井坂事務所'!F27) | C32: =IF(N('岡崎事務所'!F27)=0,"",'岡崎事務所'!F27) | D32: =IF(N('綾測'!F27)=0,"",'綾測'!F27) | E32: =IF(SUM(B32:D32)=0,"",SUM(B32:D32)) | F32: =IF(N('井坂事務所'!D27)=0,"",'井坂事務所'!D27) | G32: =IF(N('岡崎事務所'!D27)=0,"",'岡崎事務所'!D27) | H32: =IF(N('綾測'!D27)=0,"",'綾測'!D27) | I32: =IF(SUM(F32:H32)=0,"",SUM(F32:H32)) | J32: =IF(N('井坂事務所'!E27)=0,"",'井坂事務所'!E27) | K32: =IF(N('岡崎事務所'!E27)=0,"",'岡崎事務所'!E27) | L32: =IF(N('綾測'!E27)=0,"",'綾測'!E27) | M32: =IF(SUM(J32:L32)=0,"",SUM(J32:L32))
A33: ='井坂事務所'!A28 | B33: =IF(N('井坂事務所'!F28)=0,"",'井坂事務所'!F28) | C33: =IF(N('岡崎事務所'!F28)=0,"",'岡崎事務所'!F28) | D33: =IF(N('綾測'!F28)=0,"",'綾測'!F28) | E33: =IF(SUM(B33:D33)=0,"",SUM(B33:D33)) | F33: =IF(N('井坂事務所'!D28)=0,"",'井坂事務所'!D28) | G33: =IF(N('岡崎事務所'!D28)=0,"",'岡崎事務所'!D28) | H33: =IF(N('綾測'!D28)=0,"",'綾測'!D28) | I33: =IF(SUM(F33:H33)=0,"",SUM(F33:H33)) | J33: =IF(N('井坂事務所'!E28)=0,"",'井坂事務所'!E28) | K33: =IF(N('岡崎事務所'!E28)=0,"",'岡崎事務所'!E28) | L33: =IF(N('綾測'!E28)=0,"",'綾測'!E28) | M33: =IF(SUM(J33:L33)=0,"",SUM(J33:L33))
A34: ='井坂事務所'!A29 | B34: =IF(N('井坂事務所'!F29)=0,"",'井坂事務所'!F29) | C34: =IF(N('岡崎事務所'!F29)=0,"",'岡崎事務所'!F29) | D34: =IF(N('綾測'!F29)=0,"",'綾測'!F29) | E34: =IF(SUM(B34:D34)=0,"",SUM(B34:D34)) | F34: =IF(N('井坂事務所'!D29)=0,"",'井坂事務所'!D29) | G34: =IF(N('岡崎事務所'!D29)=0,"",'岡崎事務所'!D29) | H34: =IF(N('綾測'!D29)=0,"",'綾測'!D29) | I34: =IF(SUM(F34:H34)=0,"",SUM(F34:H34)) | J34: =IF(N('井坂事務所'!E29)=0,"",'井坂事務所'!E29) | K34: =IF(N('岡崎事務所'!E29)=0,"",'岡崎事務所'!E29) | L34: =IF(N('綾測'!E29)=0,"",'綾測'!E29) | M34: =IF(SUM(J34:L34)=0,"",SUM(J34:L34))
A35: ='井坂事務所'!A30 | B35: =IF(N('井坂事務所'!F30)=0,"",'井坂事務所'!F30) | C35: =IF(N('岡崎事務所'!F30)=0,"",'岡崎事務所'!F30) | D35: =IF(N('綾測'!F30)=0,"",'綾測'!F30) | E35: =IF(SUM(B35:D35)=0,"",SUM(B35:D35)) | F35: =IF(N('井坂事務所'!D30)=0,"",'井坂事務所'!D30) | G35: =IF(N('岡崎事務所'!D30)=0,"",'岡崎事務所'!D30) | H35: =IF(N('綾測'!D30)=0,"",'綾測'!D30) | I35: =IF(SUM(F35:H35)=0,"",SUM(F35:H35)) | J35: =IF(N('井坂事務所'!E30)=0,"",'井坂事務所'!E30) | K35: =IF(N('岡崎事務所'!E30)=0,"",'岡崎事務所'!E30) | L35: =IF(N('綾測'!E30)=0,"",'綾測'!E30) | M35: =IF(SUM(J35:L35)=0,"",SUM(J35:L35))
A36: ='井坂事務所'!A31 | B36: =IF(N('井坂事務所'!F31)=0,"",'井坂事務所'!F31) | C36: =IF(N('岡崎事務所'!F31)=0,"",'岡崎事務所'!F31) | D36: =IF(N('綾測'!F31)=0,"",'綾測'!F31) | E36: =IF(SUM(B36:D36)=0,"",SUM(B36:D36)) | F36: =IF(N('井坂事務所'!D31)=0,"",'井坂事務所'!D31) | G36: =IF(N('岡崎事務所'!D31)=0,"",'岡崎事務所'!D31) | H36: =IF(N('綾測'!D31)=0,"",'綾測'!D31) | I36: =IF(SUM(F36:H36)=0,"",SUM(F36:H36)) | J36: =IF(N('井坂事務所'!E31)=0,"",'井坂事務所'!E31) | K36: =IF(N('岡崎事務所'!E31)=0,"",'岡崎事務所'!E31) | L36: =IF(N('綾測'!E31)=0,"",'綾測'!E31) | M36: =IF(SUM(J36:L36)=0,"",SUM(J36:L36))
A37: ='井坂事務所'!A32 | B37: =IF(N('井坂事務所'!F32)=0,"",'井坂事務所'!F32) | C37: =IF(N('岡崎事務所'!F32)=0,"",'岡崎事務所'!F32) | D37: =IF(N('綾測'!F32)=0,"",'綾測'!F32) | E37: =IF(SUM(B37:D37)=0,"",SUM(B37:D37)) | F37: =IF(N('井坂事務所'!D32)=0,"",'井坂事務所'!D32) | G37: =IF(N('岡崎事務所'!D32)=0,"",'岡崎事務所'!D32) | H37: =IF(N('綾測'!D32)=0,"",'綾測'!D32) | I37: =IF(SUM(F37:H37)=0,"",SUM(F37:H37)) | J37: =IF(N('井坂事務所'!E32)=0,"",'井坂事務所'!E32) | K37: =IF(N('岡崎事務所'!E32)=0,"",'岡崎事務所'!E32) | L37: =IF(N('綾測'!E32)=0,"",'綾測'!E32) | M37: =IF(SUM(J37:L37)=0,"",SUM(J37:L37))
A38: ='井坂事務所'!A33 | B38: =IF(N('井坂事務所'!F33)=0,"",'井坂事務所'!F33) | C38: =IF(N('岡崎事務所'!F33)=0,"",'岡崎事務所'!F33) | D38: =IF(N('綾測'!F33)=0,"",'綾測'!F33) | E38: =IF(SUM(B38:D38)=0,"",SUM(B38:D38)) | F38: =IF(N('井坂事務所'!D33)=0,"",'井坂事務所'!D33) | G38: =IF(N('岡崎事務所'!D33)=0,"",'岡崎事務所'!D33) | H38: =IF(N('綾測'!D33)=0,"",'綾測'!D33) | I38: =IF(SUM(F38:H38)=0,"",SUM(F38:H38)) | J38: =IF(N('井坂事務所'!E33)=0,"",'井坂事務所'!E33) | K38: =IF(N('岡崎事務所'!E33)=0,"",'岡崎事務所'!E33) | L38: =IF(N('綾測'!E33)=0,"",'綾測'!E33) | M38: =IF(SUM(J38:L38)=0,"",SUM(J38:L38))
A39: ='井坂事務所'!A34 | B39: =IF(N('井坂事務所'!F34)=0,"",'井坂事務所'!F34) | C39: =IF(N('岡崎事務所'!F34)=0,"",'岡崎事務所'!F34) | D39: =IF(N('綾測'!F34)=0,"",'綾測'!F34) | E39: =IF(SUM(B39:D39)=0,"",SUM(B39:D39)) | F39: =IF(N('井坂事務所'!D34)=0,"",'井坂事務所'!D34) | G39: =IF(N('岡崎事務所'!D34)=0,"",'岡崎事務所'!D34) | H39: =IF(N('綾測'!D34)=0,"",'綾測'!D34) | I39: =IF(SUM(F39:H39)=0,"",SUM(F39:H39)) | J39: =IF(N('井坂事務所'!E34)=0,"",'井坂事務所'!E34) | K39: =IF(N('岡崎事務所'!E34)=0,"",'岡崎事務所'!E34) | L39: =IF(N('綾測'!E34)=0,"",'綾測'!E34) | M39: =IF(SUM(J39:L39)=0,"",SUM(J39:L39))
A40: ='井坂事務所'!A35 | B40: =IF(N('井坂事務所'!F35)=0,"",'井坂事務所'!F35) | C40: =IF(N('岡崎事務所'!F35)=0,"",'岡崎事務所'!F35) | D40: =IF(N('綾測'!F35)=0,"",'綾測'!F35) | E40: =IF(SUM(B40:D40)=0,"",SUM(B40:D40)) | F40: =IF(N('井坂事務所'!D35)=0,"",'井坂事務所'!D35) | G40: =IF(N('岡崎事務所'!D35)=0,"",'岡崎事務所'!D35) | H40: =IF(N('綾測'!D35)=0,"",'綾測'!D35) | I40: =IF(SUM(F40:H40)=0,"",SUM(F40:H40)) | J40: =IF(N('井坂事務所'!E35)=0,"",'井坂事務所'!E35) | K40: =IF(N('岡崎事務所'!E35)=0,"",'岡崎事務所'!E35) | L40: =IF(N('綾測'!E35)=0,"",'綾測'!E35) | M40: =IF(SUM(J40:L40)=0,"",SUM(J40:L40))
A41: ='井坂事務所'!A36 | B41: =IF(N('井坂事務所'!F36)=0,"",'井坂事務所'!F36) | C41: =IF(N('岡崎事務所'!F36)=0,"",'岡崎事務所'!F36) | D41: =IF(N('綾測'!F36)=0,"",'綾測'!F36) | E41: =IF(SUM(B41:D41)=0,"",SUM(B41:D41)) | F41: =IF(N('井坂事務所'!D36)=0,"",'井坂事務所'!D36) | G41: =IF(N('岡崎事務所'!D36)=0,"",'岡崎事務所'!D36) | H41: =IF(N('綾測'!D36)=0,"",'綾測'!D36) | I41: =IF(SUM(F41:H41)=0,"",SUM(F41:H41)) | J41: =IF(N('井坂事務所'!E36)=0,"",'井坂事務所'!E36) | K41: =IF(N('岡崎事務所'!E36)=0,"",'岡崎事務所'!E36) | L41: =IF(N('綾測'!E36)=0,"",'綾測'!E36) | M41: =IF(SUM(J41:L41)=0,"",SUM(J41:L41))
...

Sheet 井坂事務所
A1: 支払日 | B1: 請求額（税抜き） | C1: 消費税額 | D1: 請求額（税込み） | E1: 源泉徴収額 | F1: 振込額 | G1: 銀行通帳の振込額
A2: 46053 | B2: 1080400 | C2: =B2*0.1 | D2: =B2+C2 | E2: =IF(D2<=1000000,ROUNDDOWN(D2*0.1021,0),ROUNDDOWN(1000000*0.1021+(D2-1000000)*0.2042,0)) | F2: =D2-E2 | G2: 1047861
A3: 46081 | B3: 1199709 | C3: =B3*0.1 | D3: =B3+C3 | E3: =IF(D3<=1000000,ROUNDDOWN(D3*0.1021,0),ROUNDDOWN(1000000*0.1021+(D3-1000000)*0.2042,0)) | F3: =D3-E3 | G3: 1152302
A4: 46112 | B4: 2022800 | C4: =B4*0.1 | D4: =B4+C4 | E4: =IF(D4<=1000000,ROUNDDOWN(D4*0.1021,0),ROUNDDOWN(1000000*0.1021+(D4-1000000)*0.2042,0)) | F4: =D4-E4 | G4: 1872819
A5: 46142 | B5: 2015200 | C5: =B5*0.1 | D5: =B5+C5 | E5: =IF(D5<=1000000,ROUNDDOWN(D5*0.1021,0),ROUNDDOWN(1000000*0.1021+(D5-1000000)*0.2042,0)) | F5: =D5-E5 | G5: 1866166
A6: 46173 | B6: 2087000 | C6: =B6*0.1 | D6: =B6+C6 | E6: =IF(D6<=1000000,ROUNDDOWN(D6*0.1021,0),ROUNDDOWN(1000000*0.1021+(D6-1000000)*0.2042,0)) | F6: =D6-E6 | G6: 1929019
A7: 46203 | B7: 2087200 | C7: =B7*0.1 | D7: =B7+C7 | E7: =IF(D7<=1000000,ROUNDDOWN(D7*0.1021,0),ROUNDDOWN(1000000*0.1021+(D7-1000000)*0.2042,0)) | F7: =D7-E7 | G7: 1929194
A8: 46234 | B8: 2233600 | C8: =B8*0.1 | D8: =B8+C8 | E8: =IF(D8<=1000000,ROUNDDOWN(D8*0.1021,0),ROUNDDOWN(1000000*0.1021+(D8-1000000)*0.2042,0)) | F8: =D8-E8 | G8: 2057349
A9: 46265 | B9: 374400 | C9: =B9*0.1 | D9: =B9+C9 | E9: =IF(D9<=1000000,ROUNDDOWN(D9*0.1021,0),ROUNDDOWN(1000000*0.1021+(D9-1000000)*0.2042,0)) | F9: =D9-E9
A10: 46295 | C10: =B10*0.1 | D10: =B10+C10 | E10: =IF(D10<=1000000,ROUNDDOWN(D10*0.1021,0),ROUNDDOWN(1000000*0.1021+(D10-1000000)*0.2042,0)) | F10: =D10-E10
A11: 46326 | C11: =B11*0.1 | D11: =B11+C11 | E11: =IF(D11<=1000000,ROUNDDOWN(D11*0.1021,0),ROUNDDOWN(1000000*0.1021+(D11-1000000)*0.2042,0)) | F11: =D11-E11
A12: 46356 | C12: =B12*0.1 | D12: =B12+C12 | E12: =IF(D12<=1000000,ROUNDDOWN(D12*0.1021,0),ROUNDDOWN(1000000*0.1021+(D12-1000000)*0.2042,0)) | F12: =D12-E12
A13: 46387 | C13: =B13*0.1 | D13: =B13+C13 | E13: =IF(D13<=1000000,ROUNDDOWN(D13*0.1021,0),ROUNDDOWN(1000000*0.1021+(D13-1000000)*0.2042,0)) | F13: =D13-E13
A14: 46418 | C14: =B14*0.1 | D14: =B14+C14 | E14: =IF(D14<=1000000,ROUNDDOWN(D14*0.1021,0),ROUNDDOWN(1000000*0.1021+(D14-1000000)*0.2042,0)) | F14: =D14-E14
A15: 46446 | C15: =B15*0.1 | D15: =B15+C15 | E15: =IF(D15<=1000000,ROUNDDOWN(D15*0.1021,0),ROUNDDOWN(1000000*0.1021+(D15-1000000)*0.2042,0)) | F15: =D15-E15
A16: 46477 | C16: =B16*0.1 | D16: =B16+C16 | E16: =IF(D16<=1000000,ROUNDDOWN(D16*0.1021,0),ROUNDDOWN(1000000*0.1021+(D16-1000000)*0.2042,0)) | F16: =D16-E16
A17: 46507 | C17: =B17*0.1 | D17: =B17+C17 | E17: =IF(D17<=1000000,ROUNDDOWN(D17*0.1021,0),ROUNDDOWN(1000000*0.1021+(D17-1000000)*0.2042,0)) | F17: =D17-E17
A18: 46538 | C18: =B18*0.1 | D18: =B18+C18 | E18: =IF(D18<=1000000,ROUNDDOWN(D18*0.1021,0),ROUNDDOWN(1000000*0.1021+(D18-1000000)*0.2042,0)) | F18: =D18-E18
A19: 46568 | C19: =B19*0.1 | D19: =B19+C19 | E19: =IF(D19<=1000000,ROUNDDOWN(D19*0.1021,0),ROUNDDOWN(1000000*0.1021+(D19-1000000)*0.2042,0)) | F19: =D19-E19
A20: 46599 | C20: =B20*0.1 | D20: =B20+C20 | E20: =IF(D20<=1000000,ROUNDDOWN(D20*0.1021,0),ROUNDDOWN(1000000*0.1021+(D20-1000000)*0.2042,0)) | F20: =D20-E20
A21: 46630 | C21: =B21*0.1 | D21: =B21+C21 | E21: =IF(D21<=1000000,ROUNDDOWN(D21*0.1021,0),ROUNDDOWN(1000000*0.1021+(D21-1000000)*0.2042,0)) | F21: =D21-E21
... A37: 47118 | C37: =B37*0.1 | D37: =B37+C37 | E37: =IF(D37<=1000000,ROUNDDOWN(D37*0.1021,0),ROUNDDOWN(1000000*0.1021+(D37-1000000)*0.2042,0)) | F37: =D37-E37

Sheet 岡崎事務所
A1: 支払日 | B1: 請求額（税抜き） | C1: 消費税額 | D1: 請求額（税込み） | E1: 源泉徴収額 | F1: 振込額
A2: 46053 | C2: =B2*0.1 | D2: =B2+C2 | E2: =IF(D2<=1000000,ROUNDDOWN(D2*0.1021,0),ROUNDDOWN(1000000*0.1021+(D2-1000000)*0.2042,0)) | F2: =D2-E2
A3: 46081 | C3: =B3*0.1 | D3: =B3+C3 | E3: =IF(D3<=1000000,ROUNDDOWN(D3*0.1021,0),ROUNDDOWN(1000000*0.1021+(D3-1000000)*0.2042,0)) | F3: =D3-E3
A4: 46112 | B4: 1016320 | C4: =B4*0.1 | D4: =B4+C4 | E4: =IF(D4<=1000000,ROUNDDOWN(D4*0.1021,0),ROUNDDOWN(1000000*0.1021+(D4-1000000)*0.2042,0)) | F4: =D4-E4
A5: 46142 | B5: 849560 | C5: =B5*0.1 | D5: =B5+C5 | E5: =IF(D5<=1000000,ROUNDDOWN(D5*0.1021,0),ROUNDDOWN(1000000*0.1021+(D5-1000000)*0.2042,0)) | F5: =D5-E5
A6: 46173 | B6: 784080 | C6: =B6*0.1 | D6: =B6+C6 | E6: =IF(D6<=1000000,ROUNDDOWN(D6*0.1021,0),ROUNDDOWN(1000000*0.1021+(D6-1000000)*0.2042,0)) | F6: =D6-E6
A7: 46203 | B7: 641280 | C7: =B7*0.1 | D7: =B7+C7 | E7: =IF(D7<=1000000,ROUNDDOWN(D7*0.1021,0),ROUNDDOWN(1000000*0.1021+(D7-1000000)*0.2042,0)) | F7: =D7-E7
A8: 46234 | B8: 1366480 | C8: =B8*0.1 | D8: =B8+C8 | E8: =IF(D8<=1000000,ROUNDDOWN(D8*0.1021,0),ROUNDDOWN(1000000*0.1021+(D8-1000000)*0.2042,0)) | F8: =D8-E8
A9: 46265 | B9: 0 | C9: =B9*0.1 | D9: =B9+C9 | E9: =IF(D9<=1000000,ROUNDDOWN(D9*0.1021,0),ROUNDDOWN(1000000*0.1021+(D9-1000000)*0.2042,0)) | F9: =D9-E9
A10: 46295 | C10: =B10*0.1 | D10: =B10+C10 | E10: =IF(D10<=1000000,ROUNDDOWN(D10*0.1021,0),ROUNDDOWN(1000000*0.1021+(D10-1000000)*0.2042,0)) | F10: =D10-E10
A11: 46326 | C11: =B11*0.1 | D11: =B11+C11 | E11: =IF(D11<=1000000,ROUNDDOWN(D11*0.1021,0),ROUNDDOWN(1000000*0.1021+(D11-1000000)*0.2042,0)) | F11: =D11-E11
A12: 46356 | C12: =B12*0.1 | D12: =B12+C12 | E12: =IF(D12<=1000000,ROUNDDOWN(D12*0.1021,0),ROUNDDOWN(1000000*0.1021+(D12-1000000)*0.2042,0)) | F12: =D12-E12
A13: 46387 | C13: =B13*0.1 | D13: =B13+C13 | E13: =IF(D13<=1000000,ROUNDDOWN(D13*0.1021,0),ROUNDDOWN(1000000*0.1021+(D13-1000000)*0.2042,0)) | F13: =D13-E13
A14: 46418 | C14: =B14*0.1 | D14: =B14+C14 | E14: =IF(D14<=1000000,ROUNDDOWN(D14*0.1021,0),ROUNDDOWN(1000000*0.1021+(D14-1000000)*0.2042,0)) | F14: =D14-E14
A15: 46446 | C15: =B15*0.1 | D15: =B15+C15 | E15: =IF(D15<=1000000,ROUNDDOWN(D15*0.1021,0),ROUNDDOWN(1000000*0.1021+(D15-1000000)*0.2042,0)) | F15: =D15-E15
A16: 46477 | C16: =B16*0.1 | D16: =B16+C16 | E16: =IF(D16<=1000000,ROUNDDOWN(D16*0.1021,0),ROUNDDOWN(1000000*0.1021+(D16-1000000)*0.2042,0)) | F16: =D16-E16
A17: 46507 | C17: =B17*0.1 | D17: =B17+C17 | E17: =IF(D17<=1000000,ROUNDDOWN(D17*0.1021,0),ROUNDDOWN(1000000*0.1021+(D17-1000000)*0.2042,0)) | F17: =D17-E17
A18: 46538 | C18: =B18*0.1 | D18: =B18+C18 | E18: =IF(D18<=1000000,ROUNDDOWN(D18*0.1021,0),ROUNDDOWN(1000000*0.1021+(D18-1000000)*0.2042,0)) | F18: =D18-E18
A19: 46568 | C19: =B19*0.1 | D19: =B19+C19 | E19: =IF(D19<=1000000,ROUNDDOWN(D19*0.1021,0),ROUNDDOWN(1000000*0.1021+(D19-1000000)*0.2042,0)) | F19: =D19-E19
A20: 46599 | C20: =B20*0.1 | D20: =B20+C20 | E20: =IF(D20<=1000000,ROUNDDOWN(D20*0.1021,0),ROUNDDOWN(1000000*0.1021+(D20-1000000)*0.2042,0)) | F20: =D20-E20
A21: 46630 | C21: =B21*0.1 | D21: =B21+C21 | E21: =IF(D21<=1000000,ROUNDDOWN(D21*0.1021,0),ROUNDDOWN(1000000*0.1021+(D21-1000000)*0.2042,0)) | F21: =D21-E21
... A37: 47118 | C37: =B37*0.1 | D37: =B37+C37 | E37: =IF(D37<=1000000,ROUNDDOWN(D37*0.1021,0),ROUNDDOWN(1000000*0.1021+(D37-1000000)*0.2042,0)) | F37: =D37-E37

Sheet 綾測
A1: 支払日 | B1: 請求額（税抜き） | C1: 消費税額 | D1: 請求額（税込み） | E1: 源泉徴収額 | F1: 振込額
A2: 46053 | B2: 708360 | C2: =B2*0.1 | D2: =B2+C2 | E2: =IF(B2<=1000000,ROUNDUP(B2*0.1021,0),ROUNDUP(1000000*0.1021+(B2-1000000)*0.2042,0)) | F2: =D2-E2
A3: 46081 | B3: 743130 | C3: =B3*0.1 | D3: =B3+C3 | E3: =IF(B3<=1000000,ROUNDUP(B3*0.1021,0),ROUNDUP(1000000*0.1021+(B3-1000000)*0.2042,0)) | F3: =D3-E3
A4: 46112 | B4: 745570 | C4: =B4*0.1 | D4: =B4+C4 | E4: =IF(B4<=1000000,ROUNDUP(B4*0.1021,0),ROUNDUP(1000000*0.1021+(B4-1000000)*0.2042,0)) | F4: =D4-E4
A5: 46142 | B5: 776140 | C5: =B5*0.1 | D5: =B5+C5 | E5: =IF(B5<=1000000,ROUNDUP(B5*0.1021,0),ROUNDUP(1000000*0.1021+(B5-1000000)*0.2042,0)) | F5: =D5-E5
A6: 46173 | B6: 789430 | C6: =B6*0.1 | D6: =B6+C6 | E6: =IF(B6<=1000000,ROUNDUP(B6*0.1021,0),ROUNDUP(1000000*0.1021+(B6-1000000)*0.2042,0)) | F6: =D6-E6
A7: 46203 | B7: 872280 | C7: =B7*0.1 | D7: =B7+C7 | E7: =IF(B7<=1000000,ROUNDUP(B7*0.1021,0),ROUNDUP(1000000*0.1021+(B7-1000000)*0.2042,0)) | F7: =D7-E7
A8: 46234 | B8: 766160 | C8: =B8*0.1 | D8: =B8+C8 | E8: =IF(B8<=1000000,ROUNDUP(B8*0.1021,0),ROUNDUP(1000000*0.1021+(B8-1000000)*0.2042,0)) | F8: =D8-E8
A9: 46265 | B9: 703228 | C9: =B9*0.1 | D9: =B9+C9 | E9: =IF(B9<=1000000,ROUNDUP(B9*0.1021,0),ROUNDUP(1000000*0.1021+(B9-1000000)*0.2042,0)) | F9: =D9-E9
A10: 46295 | C10: =B10*0.1 | D10: =B10+C10 | E10: =IF(B10<=1000000,ROUNDUP(B10*0.1021,0),ROUNDUP(1000000*0.1021+(B10-1000000)*0.2042,0)) | F10: =D10-E10
A11: 46326 | C11: =B11*0.1 | D11: =B11+C11 | E11: =IF(B11<=1000000,ROUNDUP(B11*0.1021,0),ROUNDUP(1000000*0.1021+(B11-1000000)*0.2042,0)) | F11: =D11-E11
A12: 46356 | C12: =B12*0.1 | D12: =B12+C12 | E12: =IF(B12<=1000000,ROUNDUP(B12*0.1021,0),ROUNDUP(1000000*0.1021+(B12-1000000)*0.2042,0)) | F12: =D12-E12
A13: 46387 | C13: =B13*0.1 | D13: =B13+C13 | E13: =IF(B13<=1000000,ROUNDUP(B13*0.1021,0),ROUNDUP(1000000*0.1021+(B13-1000000)*0.2042,0)) | F13: =D13-E13
A14: 46418 | C14: =B14*0.1 | D14: =B14+C14 | E14: =IF(B14<=1000000,ROUNDUP(B14*0.1021,0),ROUNDUP(1000000*0.1021+(B14-1000000)*0.2042,0)) | F14: =D14-E14
A15: 46446 | C15: =B15*0.1 | D15: =B15+C15 | E15: =IF(B15<=1000000,ROUNDUP(B15*0.1021,0),ROUNDUP(1000000*0.1021+(B15-1000000)*0.2042,0)) | F15: =D15-E15
A16: 46477 | C16: =B16*0.1 | D16: =B16+C16 | E16: =IF(B16<=1000000,ROUNDUP(B16*0.1021,0),ROUNDUP(1000000*0.1021+(B16-1000000)*0.2042,0)) | F16: =D16-E16
A17: 46507 | C17: =B17*0.1 | D17: =B17+C17 | E17: =IF(B17<=1000000,ROUNDUP(B17*0.1021,0),ROUNDUP(1000000*0.1021+(B17-1000000)*0.2042,0)) | F17: =D17-E17
A18: 46538 | C18: =B18*0.1 | D18: =B18+C18 | E18: =IF(B18<=1000000,ROUNDUP(B18*0.1021,0),ROUNDUP(1000000*0.1021+(B18-1000000)*0.2042,0)) | F18: =D18-E18
A19: 46568 | C19: =B19*0.1 | D19: =B19+C19 | E19: =IF(B19<=1000000,ROUNDUP(B19*0.1021,0),ROUNDUP(1000000*0.1021+(B19-1000000)*0.2042,0)) | F19: =D19-E19
A20: 46599 | C20: =B20*0.1 | D20: =B20+C20 | E20: =IF(B20<=1000000,ROUNDUP(B20*0.1021,0),ROUNDUP(1000000*0.1021+(B20-1000000)*0.2042,0)) | F20: =D20-E20
A21: 46630 | C21: =B21*0.1 | D21: =B21+C21 | E21: =IF(B21<=1000000,ROUNDUP(B21*0.1021,0),ROUNDUP(1000000*0.1021+(B21-1000000)*0.2042,0)) | F21: =D21-E21
... A37: 47118 | C37: =B37*0.1 | D37: =B37+C37 | E37: =IF(B37<=1000000,ROUNDUP(B37*0.1021,0),ROUNDUP(1000000*0.1021+(B37-1000000)*0.2042,0)) | F37: =D37-E37

Sheet 合計
A1: 支払日 | B1: 請求額（税抜き） | C1: 消費税額 | D1: 請求額（税込み） | E1: 源泉徴収額 | F1: 振込額 | G1: 銀行通帳の振込額
A2: 46053 | B2: =井坂事務所!B2+岡崎事務所!B2+綾測!B2 | C2: =井坂事務所!C2+岡崎事務所!C2+綾測!C2 | D2: =井坂事務所!D2+岡崎事務所!D2+綾測!D2 | E2: =井坂事務所!E2+岡崎事務所!E2+綾測!E2 | F2: =井坂事務所!F2+岡崎事務所!F2+綾測!F2 | G2: =井坂事務所!G2+岡崎事務所!G2+綾測!G2
A3: 46081 | B3: =井坂事務所!B3+岡崎事務所!B3+綾測!B3 | C3: =井坂事務所!C3+岡崎事務所!C3+綾測!C3 | D3: =井坂事務所!D3+岡崎事務所!D3+綾測!D3 | E3: =井坂事務所!E3+岡崎事務所!E3+綾測!E3 | F3: =井坂事務所!F3+岡崎事務所!F3+綾測!F3 | G3: =井坂事務所!G3+岡崎事務所!G3+綾測!G3
A4: 46112 | B4: =井坂事務所!B4+岡崎事務所!B4+綾測!B4 | C4: =井坂事務所!C4+岡崎事務所!C4+綾測!C4 | D4: =井坂事務所!D4+岡崎事務所!D4+綾測!D4 | E4: =井坂事務所!E4+岡崎事務所!E4+綾測!E4 | F4: =井坂事務所!F4+岡崎事務所!F4+綾測!F4 | G4: =井坂事務所!G4+岡崎事務所!G4+綾測!G4
A5: 46142 | B5: =井坂事務所!B5+岡崎事務所!B5+綾測!B5 | C5: =井坂事務所!C5+岡崎事務所!C5+綾測!C5 | D5: =井坂事務所!D5+岡崎事務所!D5+綾測!D5 | E5: =井坂事務所!E5+岡崎事務所!E5+綾測!E5 | F5: =井坂事務所!F5+岡崎事務所!F5+綾測!F5 | G5: =井坂事務所!G5+岡崎事務所!G5+綾測!G5
A6: 46173 | B6: =井坂事務所!B6+岡崎事務所!B6+綾測!B6 | C6: =井坂事務所!C6+岡崎事務所!C6+綾測!C6 | D6: =井坂事務所!D6+岡崎事務所!D6+綾測!D6 | E6: =井坂事務所!E6+岡崎事務所!E6+綾測!E6 | F6: =井坂事務所!F6+岡崎事務所!F6+綾測!F6 | G6: =井坂事務所!G6+岡崎事務所!G6+綾測!G6
A7: 46203 | B7: =井坂事務所!B7+岡崎事務所!B7+綾測!B7 | C7: =井坂事務所!C7+岡崎事務所!C7+綾測!C7 | D7: =井坂事務所!D7+岡崎事務所!D7+綾測!D7 | E7: =井坂事務所!E7+岡崎事務所!E7+綾測!E7 | F7: =井坂事務所!F7+岡崎事務所!F7+綾測!F7 | G7: =井坂事務所!G7+岡崎事務所!G7+綾測!G7
A8: 46234 | B8: =井坂事務所!B8+岡崎事務所!B8+綾測!B8 | C8: =井坂事務所!C8+岡崎事務所!C8+綾測!C8 | D8: =井坂事務所!D8+岡崎事務所!D8+綾測!D8 | E8: =井坂事務所!E8+岡崎事務所!E8+綾測!E8 | F8: =井坂事務所!F8+岡崎事務所!F8+綾測!F8 | G8: =井坂事務所!G8+岡崎事務所!G8+綾測!G8 | I8: =4802864-682674
A9: 46265 | B9: =井坂事務所!B9+岡崎事務所!B9+綾測!B9 | C9: =井坂事務所!C9+岡崎事務所!C9+綾測!C9 | D9: =井坂事務所!D9+岡崎事務所!D9+綾測!D9 | E9: =井坂事務所!E9+岡崎事務所!E9+綾測!E9 | F9: =井坂事務所!F9+岡崎事務所!F9+綾測!F9 | G9: =井坂事務所!G9+岡崎事務所!G9+綾測!G9
A10: 46295 | B10: =井坂事務所!B10+岡崎事務所!B10+綾測!B10 | C10: =井坂事務所!C10+岡崎事務所!C10+綾測!C10 | D10: =井坂事務所!D10+岡崎事務所!D10+綾測!D10 | E10: =井坂事務所!E10+岡崎事務所!E10+綾測!E10 | F10: =井坂事務所!F10+岡崎事務所!F10+綾測!F10 | G10: =井坂事務所!G10+岡崎事務所!G10+綾測!G10
A11: 46326 | B11: =井坂事務所!B11+岡崎事務所!B11+綾測!B11 | C11: =井坂事務所!C11+岡崎事務所!C11+綾測!C11 | D11: =井坂事務所!D11+岡崎事務所!D11+綾測!D11 | E11: =井坂事務所!E11+岡崎事務所!E11+綾測!E11 | F11: =井坂事務所!F11+岡崎事務所!F11+綾測!F11 | G11: =井坂事務所!G11+岡崎事務所!G11+綾測!G11
A12: 46356 | B12: =井坂事務所!B12+岡崎事務所!B12+綾測!B12 | C12: =井坂事務所!C12+岡崎事務所!C12+綾測!C12 | D12: =井坂事務所!D12+岡崎事務所!D12+綾測!D12 | E12: =井坂事務所!E12+岡崎事務所!E12+綾測!E12 | F12: =井坂事務所!F12+岡崎事務所!F12+綾測!F12 | G12: =井坂事務所!G12+岡崎事務所!G12+綾測!G12
A13: 46387 | B13: =井坂事務所!B13+岡崎事務所!B13+綾測!B13 | C13: =井坂事務所!C13+岡崎事務所!C13+綾測!C13 | D13: =井坂事務所!D13+岡崎事務所!D13+綾測!D13 | E13: =井坂事務所!E13+岡崎事務所!E13+綾測!E13 | F13: =井坂事務所!F13+岡崎事務所!F13+綾測!F13 | G13: =井坂事務所!G13+岡崎事務所!G13+綾測!G13
A14: 46418 | B14: =井坂事務所!B14+岡崎事務所!B14+綾測!B14 | C14: =井坂事務所!C14+岡崎事務所!C14+綾測!C14 | D14: =井坂事務所!D14+岡崎事務所!D14+綾測!D14 | E14: =井坂事務所!E14+岡崎事務所!E14+綾測!E14 | F14: =井坂事務所!F14+岡崎事務所!F14+綾測!F14 | G14: =井坂事務所!G14+岡崎事務所!G14+綾測!G14
A15: 46446 | B15: =井坂事務所!B15+岡崎事務所!B15+綾測!B15 | C15: =井坂事務所!C15+岡崎事務所!C15+綾測!C15 | D15: =井坂事務所!D15+岡崎事務所!D15+綾測!D15 | E15: =井坂事務所!E15+岡崎事務所!E15+綾測!E15 | F15: =井坂事務所!F15+岡崎事務所!F15+綾測!F15 | G15: =井坂事務所!G15+岡崎事務所!G15+綾測!G15
A16: 46477 | B16: =井坂事務所!B16+岡崎事務所!B16+綾測!B16 | C16: =井坂事務所!C16+岡崎事務所!C16+綾測!C16 | D16: =井坂事務所!D16+岡崎事務所!D16+綾測!D16 | E16: =井坂事務所!E16+岡崎事務所!E16+綾測!E16 | F16: =井坂事務所!F16+岡崎事務所!F16+綾測!F16 | G16: =井坂事務所!G16+岡崎事務所!G16+綾測!G16
A17: 46507 | B17: =井坂事務所!B17+岡崎事務所!B17+綾測!B17 | C17: =井坂事務所!C17+岡崎事務所!C17+綾測!C17 | D17: =井坂事務所!D17+岡崎事務所!D17+綾測!D17 | E17: =井坂事務所!E17+岡崎事務所!E17+綾測!E17 | F17: =井坂事務所!F17+岡崎事務所!F17+綾測!F17 | G17: =井坂事務所!G17+岡崎事務所!G17+綾測!G17
A18: 46538 | B18: =井坂事務所!B18+岡崎事務所!B18+綾測!B18 | C18: =井坂事務所!C18+岡崎事務所!C18+綾測!C18 | D18: =井坂事務所!D18+岡崎事務所!D18+綾測!D18 | E18: =井坂事務所!E18+岡崎事務所!E18+綾測!E18 | F18: =井坂事務所!F18+岡崎事務所!F18+綾測!F18 | G18: =井坂事務所!G18+岡崎事務所!G18+綾測!G18
A19: 46568 | B19: =井坂事務所!B19+岡崎事務所!B19+綾測!B19 | C19: =井坂事務所!C19+岡崎事務所!C19+綾測!C19 | D19: =井坂事務所!D19+岡崎事務所!D19+綾測!D19 | E19: =井坂事務所!E19+岡崎事務所!E19+綾測!E19 | F19: =井坂事務所!F19+岡崎事務所!F19+綾測!F19 | G19: =井坂事務所!G19+岡崎事務所!G19+綾測!G19
A20: 46599 | B20: =井坂事務所!B20+岡崎事務所!B20+綾測!B20 | C20: =井坂事務所!C20+岡崎事務所!C20+綾測!C20 | D20: =井坂事務所!D20+岡崎事務所!D20+綾測!D20 | E20: =井坂事務所!E20+岡崎事務所!E20+綾測!E20 | F20: =井坂事務所!F20+岡崎事務所!F20+綾測!F20 | G20: =井坂事務所!G20+岡崎事務所!G20+綾測!G20
... A37: 47118 | B37: =井坂事務所!B37+岡崎事務所!B37+綾測!B37 | C37: =井坂事務所!C37+岡崎事務所!C37+綾測!C37 | D37: =井坂事務所!D37+岡崎事務所!D37+綾測!D37 | E37: =井坂事務所!E37+岡崎事務所!E37+綾測!E37 | F37: =井坂事務所!F37+岡崎事務所!F37+綾測!F37 | G37: =井坂事務所!G37+岡崎事務所!G37+綾測!G37
