Workbook

Sheet 科目別集計
A1: 勘定科目別 月次支払合計（202606〜202705）
A2: 勘定科目 | B2: 202606 | C2: 202607 | D2: 202608 | E2: 202609 | F2: 202610 | G2: 202611 | H2: 202612 | I2: 202701 | J2: 202702 | K2: 202703 | L2: 202704 | M2: 202705 | N2: 年間合計
A3: 賃借料 | B3: ='202606'!C56 | C3: ='202607'!C56 | D3: ='202608'!C56 | E3: ='202609'!C56 | F3: ='202610'!C56 | G3: ='202611'!C56 | H3: ='202612'!C56 | I3: ='202701'!C56 | J3: ='202702'!C56 | K3: ='202703'!C56 | L3: ='202704'!C56 | M3: ='202705'!C56 | N3: =SUM(B3:M3)
A4: 修繕費 | B4: ='202606'!D56 | C4: ='202607'!D56 | D4: ='202608'!D56 | E4: ='202609'!D56 | F4: ='202610'!D56 | G4: ='202611'!D56 | H4: ='202612'!D56 | I4: ='202701'!D56 | J4: ='202702'!D56 | K4: ='202703'!D56 | L4: ='202704'!D56 | M4: ='202705'!D56 | N4: =SUM(B4:M4)
A5: 消耗品費 | B5: ='202606'!E56 | C5: ='202607'!E56 | D5: ='202608'!E56 | E5: ='202609'!E56 | F5: ='202610'!E56 | G5: ='202611'!E56 | H5: ='202612'!E56 | I5: ='202701'!E56 | J5: ='202702'!E56 | K5: ='202703'!E56 | L5: ='202704'!E56 | M5: ='202705'!E56 | N5: =SUM(B5:M5)
A6: 雑費 | B6: ='202606'!F56 | C6: ='202607'!F56 | D6: ='202608'!F56 | E6: ='202609'!F56 | F6: ='202610'!F56 | G6: ='202611'!F56 | H6: ='202612'!F56 | I6: ='202701'!F56 | J6: ='202702'!F56 | K6: ='202703'!F56 | L6: ='202704'!F56 | M6: ='202705'!F56 | N6: =SUM(B6:M6)
A7: 通信費 | B7: ='202606'!G56 | C7: ='202607'!G56 | D7: ='202608'!G56 | E7: ='202609'!G56 | F7: ='202610'!G56 | G7: ='202611'!G56 | H7: ='202612'!G56 | I7: ='202701'!G56 | J7: ='202702'!G56 | K7: ='202703'!G56 | L7: ='202704'!G56 | M7: ='202705'!G56 | N7: =SUM(B7:M7)
A8: リース料 | B8: ='202606'!H56 | C8: ='202607'!H56 | D8: ='202608'!H56 | E8: ='202609'!H56 | F8: ='202610'!H56 | G8: ='202611'!H56 | H8: ='202612'!H56 | I8: ='202701'!H56 | J8: ='202702'!H56 | K8: ='202703'!H56 | L8: ='202704'!H56 | M8: ='202705'!H56 | N8: =SUM(B8:M8)
A9: 水道光熱費 | B9: ='202606'!I56 | C9: ='202607'!I56 | D9: ='202608'!I56 | E9: ='202609'!I56 | F9: ='202610'!I56 | G9: ='202611'!I56 | H9: ='202612'!I56 | I9: ='202701'!I56 | J9: ='202702'!I56 | K9: ='202703'!I56 | L9: ='202704'!I56 | M9: ='202705'!I56 | N9: =SUM(B9:M9)
A10: 保険積立金 | B10: ='202606'!J56 | C10: ='202607'!J56 | D10: ='202608'!J56 | E10: ='202609'!J56 | F10: ='202610'!J56 | G10: ='202611'!J56 | H10: ='202612'!J56 | I10: ='202701'!J56 | J10: ='202702'!J56 | K10: ='202703'!J56 | L10: ='202704'!J56 | M10: ='202705'!J56 | N10: =SUM(B10:M10)
A11: 保険料 | B11: ='202606'!K56 | C11: ='202607'!K56 | D11: ='202608'!K56 | E11: ='202609'!K56 | F11: ='202610'!K56 | G11: ='202611'!K56 | H11: ='202612'!K56 | I11: ='202701'!K56 | J11: ='202702'!K56 | K11: ='202703'!K56 | L11: ='202704'!K56 | M11: ='202705'!K56 | N11: =SUM(B11:M11)
A12: 支払手数料 | B12: ='202606'!L56 | C12: ='202607'!L56 | D12: ='202608'!L56 | E12: ='202609'!L56 | F12: ='202610'!L56 | G12: ='202611'!L56 | H12: ='202612'!L56 | I12: ='202701'!L56 | J12: ='202702'!L56 | K12: ='202703'!L56 | L12: ='202704'!L56 | M12: ='202705'!L56 | N12: =SUM(B12:M12)
A13: 広告宣伝費 | B13: ='202606'!M56 | C13: ='202607'!M56 | D13: ='202608'!M56 | E13: ='202609'!M56 | F13: ='202610'!M56 | G13: ='202611'!M56 | H13: ='202612'!M56 | I13: ='202701'!M56 | J13: ='202702'!M56 | K13: ='202703'!M56 | L13: ='202704'!M56 | M13: ='202705'!M56 | N13: =SUM(B13:M13)
A14: 消耗品費（8%） | B14: ='202606'!N56 | C14: ='202607'!N56 | D14: ='202608'!N56 | E14: ='202609'!N56 | F14: ='202610'!N56 | G14: ='202611'!N56 | H14: ='202612'!N56 | I14: ='202701'!N56 | J14: ='202702'!N56 | K14: ='202703'!N56 | L14: ='202704'!N56 | M14: ='202705'!N56 | N14: =SUM(B14:M14)
A15: 租税公課 | B15: ='202606'!O56 | C15: ='202607'!O56 | D15: ='202608'!O56 | E15: ='202609'!O56 | F15: ='202610'!O56 | G15: ='202611'!O56 | H15: ='202612'!O56 | I15: ='202701'!O56 | J15: ='202702'!O56 | K15: ='202703'!O56 | L15: ='202704'!O56 | M15: ='202705'!O56 | N15: =SUM(B15:M15)
A16: 車輛燃料費 | B16: ='202606'!P56 | C16: ='202607'!P56 | D16: ='202608'!P56 | E16: ='202609'!P56 | F16: ='202610'!P56 | G16: ='202611'!P56 | H16: ='202612'!P56 | I16: ='202701'!P56 | J16: ='202702'!P56 | K16: ='202703'!P56 | L16: ='202704'!P56 | M16: ='202705'!P56 | N16: =SUM(B16:M16)
A17: 旅費交通費 | B17: ='202606'!Q56 | C17: ='202607'!Q56 | D17: ='202608'!Q56 | E17: ='202609'!Q56 | F17: ='202610'!Q56 | G17: ='202611'!Q56 | H17: ='202612'!Q56 | I17: ='202701'!Q56 | J17: ='202702'!Q56 | K17: ='202703'!Q56 | L17: ='202704'!Q56 | M17: ='202705'!Q56 | N17: =SUM(B17:M17)
A18: 接待交際費 | B18: ='202606'!R56 | C18: ='202607'!R56 | D18: ='202608'!R56 | E18: ='202609'!R56 | F18: ='202610'!R56 | G18: ='202611'!R56 | H18: ='202612'!R56 | I18: ='202701'!R56 | J18: ='202702'!R56 | K18: ='202703'!R56 | L18: ='202704'!R56 | M18: ='202705'!R56 | N18: =SUM(B18:M18)
A19: 会議費 | B19: ='202606'!S56 | C19: ='202607'!S56 | D19: ='202608'!S56 | E19: ='202609'!S56 | F19: ='202610'!S56 | G19: ='202611'!S56 | H19: ='202612'!S56 | I19: ='202701'!S56 | J19: ='202702'!S56 | K19: ='202703'!S56 | L19: ='202704'!S56 | M19: ='202705'!S56 | N19: =SUM(B19:M19)
A20: 福利厚生費 | B20: ='202606'!T56 | C20: ='202607'!T56 | D20: ='202608'!T56 | E20: ='202609'!T56 | F20: ='202610'!T56 | G20: ='202611'!T56 | H20: ='202612'!T56 | I20: ='202701'!T56 | J20: ='202702'!T56 | K20: ='202703'!T56 | L20: ='202704'!T56 | M20: ='202705'!T56 | N20: =SUM(B20:M20)
A21: 工具、器具及び備品 | B21: ='202606'!U56 | C21: ='202607'!U56 | D21: ='202608'!U56 | E21: ='202609'!U56 | F21: ='202610'!U56 | G21: ='202611'!U56 | H21: ='202612'!U56 | I21: ='202701'!U56 | J21: ='202702'!U56 | K21: ='202703'!U56 | L21: ='202704'!U56 | M21: ='202705'!U56 | N21: =SUM(B21:M21)
A22: 車両運搬具 | B22: ='202606'!V56 | C22: ='202607'!V56 | D22: ='202608'!V56 | E22: ='202609'!V56 | F22: ='202610'!V56 | G22: ='202611'!V56 | H22: ='202612'!V56 | I22: ='202701'!V56 | J22: ='202702'!V56 | K22: ='202703'!V56 | L22: ='202704'!V56 | M22: ='202705'!V56 | N22: =SUM(B22:M22)
B23: ='202606'!W56 | C23: ='202607'!W56 | D23: ='202608'!W56 | E23: ='202609'!W56 | F23: ='202610'!W56 | G23: ='202611'!W56 | H23: ='202612'!W56 | I23: ='202701'!W56 | J23: ='202702'!W56 | K23: ='202703'!W56 | L23: ='202704'!W56 | M23: ='202705'!W56 | N23: =SUM(B23:M23)
B24: ='202606'!X56 | C24: ='202607'!X56 | D24: ='202608'!X56 | E24: ='202609'!X56 | F24: ='202610'!X56 | G24: ='202611'!X56 | H24: ='202612'!X56 | I24: ='202701'!X56 | J24: ='202702'!X56 | K24: ='202703'!X56 | L24: ='202704'!X56 | M24: ='202705'!X56 | N24: =SUM(B24:M24)
B25: ='202606'!Y56 | C25: ='202607'!Y56 | D25: ='202608'!Y56 | E25: ='202609'!Y56 | F25: ='202610'!Y56 | G25: ='202611'!Y56 | H25: ='202612'!Y56 | I25: ='202701'!Y56 | J25: ='202702'!Y56 | K25: ='202703'!Y56 | L25: ='202704'!Y56 | M25: ='202705'!Y56 | N25: =SUM(B25:M25)
A26: 合計 | B26: =SUM(B3:B25) | C26: =SUM(C3:C25) | D26: =SUM(D3:D25) | E26: =SUM(E3:E25) | F26: =SUM(F3:F25) | G26: =SUM(G3:G25) | H26: =SUM(H3:H25) | I26: =SUM(I3:I25) | ... N26: =SUM(N3:N25)
A28: ※ 各月シートの合計行から自動集計しています。金額は各月シートに入力してください。
A29: ※ A列に科目名を追記すると、全ての月シートの列見出しにも反映されます（追加枠3列）。

Sheet 支払先別集計
A1: 支払先別 月次支払合計（202606〜202705）
A2: 支払先 | B2: 202606 | C2: 202607 | D2: 202608 | E2: 202609 | F2: 202610 | G2: 202611 | H2: 202612 | I2: 202701 | J2: 202702 | K2: 202703 | L2: 202704 | M2: 202705 | N2: 年間合計
A3: =IF(支払先マスタ!A3="","",支払先マスタ!A3) | B3: ='202606'!B3 | C3: ='202607'!B3 | D3: ='202608'!B3 | E3: ='202609'!B3 | F3: ='202610'!B3 | G3: ='202611'!B3 | H3: ='202612'!B3 | I3: ='202701'!B3 | J3: ='202702'!B3 | K3: ='202703'!B3 | L3: ='202704'!B3 | M3: ='202705'!B3 | N3: =SUM(B3:M3)
A4: =IF(支払先マスタ!A4="","",支払先マスタ!A4) | B4: ='202606'!B4 | C4: ='202607'!B4 | D4: ='202608'!B4 | E4: ='202609'!B4 | F4: ='202610'!B4 | G4: ='202611'!B4 | H4: ='202612'!B4 | I4: ='202701'!B4 | J4: ='202702'!B4 | K4: ='202703'!B4 | L4: ='202704'!B4 | M4: ='202705'!B4 | N4: =SUM(B4:M4)
A5: =IF(支払先マスタ!A5="","",支払先マスタ!A5) | B5: ='202606'!B5 | C5: ='202607'!B5 | D5: ='202608'!B5 | E5: ='202609'!B5 | F5: ='202610'!B5 | G5: ='202611'!B5 | H5: ='202612'!B5 | I5: ='202701'!B5 | J5: ='202702'!B5 | K5: ='202703'!B5 | L5: ='202704'!B5 | M5: ='202705'!B5 | N5: =SUM(B5:M5)
A6: =IF(支払先マスタ!A6="","",支払先マスタ!A6) | B6: ='202606'!B6 | C6: ='202607'!B6 | D6: ='202608'!B6 | E6: ='202609'!B6 | F6: ='202610'!B6 | G6: ='202611'!B6 | H6: ='202612'!B6 | I6: ='202701'!B6 | J6: ='202702'!B6 | K6: ='202703'!B6 | L6: ='202704'!B6 | M6: ='202705'!B6 | N6: =SUM(B6:M6)
A7: =IF(支払先マスタ!A7="","",支払先マスタ!A7) | B7: ='202606'!B7 | C7: ='202607'!B7 | D7: ='202608'!B7 | E7: ='202609'!B7 | F7: ='202610'!B7 | G7: ='202611'!B7 | H7: ='202612'!B7 | I7: ='202701'!B7 | J7: ='202702'!B7 | K7: ='202703'!B7 | L7: ='202704'!B7 | M7: ='202705'!B7 | N7: =SUM(B7:M7)
A8: =IF(支払先マスタ!A8="","",支払先マスタ!A8) | B8: ='202606'!B8 | C8: ='202607'!B8 | D8: ='202608'!B8 | E8: ='202609'!B8 | F8: ='202610'!B8 | G8: ='202611'!B8 | H8: ='202612'!B8 | I8: ='202701'!B8 | J8: ='202702'!B8 | K8: ='202703'!B8 | L8: ='202704'!B8 | M8: ='202705'!B8 | N8: =SUM(B8:M8)
A9: =IF(支払先マスタ!A9="","",支払先マスタ!A9) | B9: ='202606'!B9 | C9: ='202607'!B9 | D9: ='202608'!B9 | E9: ='202609'!B9 | F9: ='202610'!B9 | G9: ='202611'!B9 | H9: ='202612'!B9 | I9: ='202701'!B9 | J9: ='202702'!B9 | K9: ='202703'!B9 | L9: ='202704'!B9 | M9: ='202705'!B9 | N9: =SUM(B9:M9)
A10: =IF(支払先マスタ!A10="","",支払先マスタ!A10) | B10: ='202606'!B10 | C10: ='202607'!B10 | D10: ='202608'!B10 | E10: ='202609'!B10 | F10: ='202610'!B10 | G10: ='202611'!B10 | H10: ='202612'!B10 | I10: ='202701'!B10 | J10: ='202702'!B10 | K10: ='202703'!B10 | L10: ='202704'!B10 | M10: ='202705'!B10 | N10: =SUM(B10:M10)
A11: =IF(支払先マスタ!A11="","",支払先マスタ!A11) | B11: ='202606'!B11 | C11: ='202607'!B11 | D11: ='202608'!B11 | E11: ='202609'!B11 | F11: ='202610'!B11 | G11: ='202611'!B11 | H11: ='202612'!B11 | I11: ='202701'!B11 | J11: ='202702'!B11 | K11: ='202703'!B11 | L11: ='202704'!B11 | M11: ='202705'!B11 | N11: =SUM(B11:M11)
A12: =IF(支払先マスタ!A12="","",支払先マスタ!A12) | B12: ='202606'!B12 | C12: ='202607'!B12 | D12: ='202608'!B12 | E12: ='202609'!B12 | F12: ='202610'!B12 | G12: ='202611'!B12 | H12: ='202612'!B12 | I12: ='202701'!B12 | J12: ='202702'!B12 | K12: ='202703'!B12 | L12: ='202704'!B12 | M12: ='202705'!B12 | N12: =SUM(B12:M12)
A13: =IF(支払先マスタ!A13="","",支払先マスタ!A13) | B13: ='202606'!B13 | C13: ='202607'!B13 | D13: ='202608'!B13 | E13: ='202609'!B13 | F13: ='202610'!B13 | G13: ='202611'!B13 | H13: ='202612'!B13 | I13: ='202701'!B13 | J13: ='202702'!B13 | K13: ='202703'!B13 | L13: ='202704'!B13 | M13: ='202705'!B13 | N13: =SUM(B13:M13)
A14: =IF(支払先マスタ!A14="","",支払先マスタ!A14) | B14: ='202606'!B14 | C14: ='202607'!B14 | D14: ='202608'!B14 | E14: ='202609'!B14 | F14: ='202610'!B14 | G14: ='202611'!B14 | H14: ='202612'!B14 | I14: ='202701'!B14 | J14: ='202702'!B14 | K14: ='202703'!B14 | L14: ='202704'!B14 | M14: ='202705'!B14 | N14: =SUM(B14:M14)
... A55: =IF(支払先マスタ!A55="","",支払先マスタ!A55) | B55: ='202606'!B55 | C55: ='202607'!B55 | D55: ='202608'!B55 | E55: ='202609'!B55 | F55: ='202610'!B55 | G55: ='202611'!B55 | H55: ='202612'!B55 | I55: ='202701'!B55 | J55: ='202702'!B55 | K55: ='202703'!B55 | L55: ='202704'!B55 | M55: ='202705'!B55 | N55: =SUM(B55:M55)
A56: 合計 | B56: =SUM(B3:B55) | C56: =SUM(C3:C55) | D56: =SUM(D3:D55) | E56: =SUM(E3:E55) | F56: =SUM(F3:F55) | G56: =SUM(G3:G55) | H56: =SUM(H3:H55) | I56: =SUM(I3:I55) | ... N56: =SUM(N3:N55)
A58: ※ 各月シートの支払先ごとの合計を並べたものです。支払先の追加は「支払先マスタ」で。

Sheet 202606
A1: 202606（2026年6月） 支払先別 × 勘定科目 | E1: ※ 支払先の追加は「支払先マスタ」／科目の追加は「科目別集計」シートで行うと全月に反映されます
A2: 支払先 | B2: 合計 | C2: =IF(科目別集計!$A3="","",科目別集計!$A3) | D2: =IF(科目別集計!$A4="","",科目別集計!$A4) | E2: =IF(科目別集計!$A5="","",科目別集計!$A5) | F2: =IF(科目別集計!$A6="","",科目別集計!$A6) | G2: =IF(科目別集計!$A7="","",科目別集計!$A7) | H2: =IF(科目別集計!$A8="","",科目別集計!$A8) | I2: =IF(科目別集計!$A9="","",科目別集計!$A9) | J2: =IF(科目別集計!$A10="","",科目別集計!$A10) | K2: =IF(科目別集計!$A11="","",科目別集計!$A11) | L2: =IF(科目別集計!$A12="","",科目別集計!$A12) | M2: =IF(科目別集計!$A13="","",科目別集計!$A13) | N2: =IF(科目別集計!$A14="","",科目別集計!$A14) | O2: =IF(科目別集計!$A15="","",科目別集計!$A15) | P2: =IF(科目別集計!$A16="","",科目別集計!$A16) | Q2: =IF(科目別集計!$A17="","",科目別集計!$A17) | R2: =IF(科目別集計!$A18="","",科目別集計!$A18) | S2: =IF(科目別集計!$A19="","",科目別集計!$A19) | T2: =IF(科目別集計!$A20="","",科目別集計!$A20) | U2: =IF(科目別集計!$A21="","",科目別集計!$A21) | V2: =IF(科目別集計!$A22="","",科目別集計!$A22) | W2: =IF(科目別集計!$A23="","",科目別集計!$A23) | X2: =IF(科目別集計!$A24="","",科目別集計!$A24) | Y2: =IF(科目別集計!$A25="","",科目別集計!$A25) | Z2: 備考
A3: =IF(支払先マスタ!A3="","",支払先マスタ!A3) | B3: =IF(COUNT(C3:Y3)=0,"",SUM(C3:Y3)) | C3: 360195
A4: =IF(支払先マスタ!A4="","",支払先マスタ!A4) | B4: =IF(COUNT(C4:Y4)=0,"",SUM(C4:Y4)) | C4: 382500
A5: =IF(支払先マスタ!A5="","",支払先マスタ!A5) | B5: =IF(COUNT(C5:Y5)=0,"",SUM(C5:Y5)) | C5: 350000
A6: =IF(支払先マスタ!A6="","",支払先マスタ!A6) | B6: =IF(COUNT(C6:Y6)=0,"",SUM(C6:Y6)) | C6: 390000
A7: =IF(支払先マスタ!A7="","",支払先マスタ!A7) | B7: =IF(COUNT(C7:Y7)=0,"",SUM(C7:Y7)) | C7: 60000
A8: =IF(支払先マスタ!A8="","",支払先マスタ!A8) | B8: =IF(COUNT(C8:Y8)=0,"",SUM(C8:Y8)) | C8: 170000
A9: =IF(支払先マスタ!A9="","",支払先マスタ!A9) | B9: =IF(COUNT(C9:Y9)=0,"",SUM(C9:Y9)) | C9: 165000
A10: =IF(支払先マスタ!A10="","",支払先マスタ!A10) | B10: =IF(COUNT(C10:Y10)=0,"",SUM(C10:Y10)) | C10: 55000
A11: =IF(支払先マスタ!A11="","",支払先マスタ!A11) | B11: =IF(COUNT(C11:Y11)=0,"",SUM(C11:Y11)) | C11: 35200
A12: =IF(支払先マスタ!A12="","",支払先マスタ!A12) | B12: =IF(COUNT(C12:Y12)=0,"",SUM(C12:Y12)) | C12: 29700
A13: =IF(支払先マスタ!A13="","",支払先マスタ!A13) | B13: =IF(COUNT(C13:Y13)=0,"",SUM(C13:Y13)) | C13: 90000
A14: =IF(支払先マスタ!A14="","",支払先マスタ!A14) | B14: =IF(COUNT(C14:Y14)=0,"",SUM(C14:Y14)) | C14: 67300
A15: =IF(支払先マスタ!A15="","",支払先マスタ!A15) | B15: =IF(COUNT(C15:Y15)=0,"",SUM(C15:Y15))
A16: =IF(支払先マスタ!A16="","",支払先マスタ!A16) | B16: =IF(COUNT(C16:Y16)=0,"",SUM(C16:Y16)) | D16: 815100
A17: =IF(支払先マスタ!A17="","",支払先マスタ!A17) | B17: =IF(COUNT(C17:Y17)=0,"",SUM(C17:Y17)) | D17: 5500
A18: =IF(支払先マスタ!A18="","",支払先マスタ!A18) | B18: =IF(COUNT(C18:Y18)=0,"",SUM(C18:Y18)) | D18: 685652
A19: =IF(支払先マスタ!A19="","",支払先マスタ!A19) | B19: =IF(COUNT(C19:Y19)=0,"",SUM(C19:Y19))
A20: =IF(支払先マスタ!A20="","",支払先マスタ!A20) | B20: =IF(COUNT(C20:Y20)=0,"",SUM(C20:Y20)) | E20: 190410
A21: =IF(支払先マスタ!A21="","",支払先マスタ!A21) | B21: =IF(COUNT(C21:Y21)=0,"",SUM(C21:Y21))
A22: =IF(支払先マスタ!A22="","",支払先マスタ!A22) | B22: =IF(COUNT(C22:Y22)=0,"",SUM(C22:Y22)) | E22: 79200
A23: =IF(支払先マスタ!A23="","",支払先マスタ!A23) | B23: =IF(COUNT(C23:Y23)=0,"",SUM(C23:Y23)) | E23: 194224
A24: =IF(支払先マスタ!A24="","",支払先マスタ!A24) | B24: =IF(COUNT(C24:Y24)=0,"",SUM(C24:Y24)) | F24: 60000
A25: =IF(支払先マスタ!A25="","",支払先マスタ!A25) | B25: =IF(COUNT(C25:Y25)=0,"",SUM(C25:Y25)) | F25: 89100
A26: =IF(支払先マスタ!A26="","",支払先マスタ!A26) | B26: =IF(COUNT(C26:Y26)=0,"",SUM(C26:Y26)) | F26: 31020
A27: =IF(支払先マスタ!A27="","",支払先マスタ!A27) | B27: =IF(COUNT(C27:Y27)=0,"",SUM(C27:Y27)) | F27: 21440
A28: =IF(支払先マスタ!A28="","",支払先マスタ!A28) | B28: =IF(COUNT(C28:Y28)=0,"",SUM(C28:Y28)) | F28: 33000
A29: =IF(支払先マスタ!A29="","",支払先マスタ!A29) | B29: =IF(COUNT(C29:Y29)=0,"",SUM(C29:Y29)) | G29: 72308
A30: =IF(支払先マスタ!A30="","",支払先マスタ!A30) | B30: =IF(COUNT(C30:Y30)=0,"",SUM(C30:Y30))
A31: =IF(支払先マスタ!A31="","",支払先マスタ!A31) | B31: =IF(COUNT(C31:Y31)=0,"",SUM(C31:Y31))
A32: =IF(支払先マスタ!A32="","",支払先マスタ!A32) | B32: =IF(COUNT(C32:Y32)=0,"",SUM(C32:Y32)) | I32: 17236
A33: =IF(支払先マスタ!A33="","",支払先マスタ!A33) | B33: =IF(COUNT(C33:Y33)=0,"",SUM(C33:Y33))
A34: =IF(支払先マスタ!A34="","",支払先マスタ!A34) | B34: =IF(COUNT(C34:Y34)=0,"",SUM(C34:Y34))
A35: =IF(支払先マスタ!A35="","",支払先マスタ!A35) | B35: =IF(COUNT(C35:Y35)=0,"",SUM(C35:Y35)) | E35: 93408
A36: =IF(支払先マスタ!A36="","",支払先マスタ!A36) | B36: =IF(COUNT(C36:Y36)=0,"",SUM(C36:Y36)) | H36: 849200
A37: =IF(支払先マスタ!A37="","",支払先マスタ!A37) | B37: =IF(COUNT(C37:Y37)=0,"",SUM(C37:Y37))
A38: =IF(支払先マスタ!A38="","",支払先マスタ!A38) | B38: =IF(COUNT(C38:Y38)=0,"",SUM(C38:Y38)) | D38: 11300
A39: =IF(支払先マスタ!A39="","",支払先マスタ!A39) | B39: =IF(COUNT(C39:Y39)=0,"",SUM(C39:Y39))
A40: =IF(支払先マスタ!A40="","",支払先マスタ!A40) | B40: =IF(COUNT(C40:Y40)=0,"",SUM(C40:Y40)) | D40: 34000
...

Sheet 202607
A1: 202607（2026年7月） 支払先別 × 勘定科目 | E1: ※ 支払先の追加は「支払先マスタ」／科目の追加は「科目別集計」シートで行うと全月に反映されます
A2: 支払先 | B2: 合計 | C2: =IF(科目別集計!$A3="","",科目別集計!$A3) | D2: =IF(科目別集計!$A4="","",科目別集計!$A4) | E2: =IF(科目別集計!$A5="","",科目別集計!$A5) | F2: =IF(科目別集計!$A6="","",科目別集計!$A6) | G2: =IF(科目別集計!$A7="","",科目別集計!$A7) | H2: =IF(科目別集計!$A8="","",科目別集計!$A8) | I2: =IF(科目別集計!$A9="","",科目別集計!$A9) | J2: =IF(科目別集計!$A10="","",科目別集計!$A10) | K2: =IF(科目別集計!$A11="","",科目別集計!$A11) | L2: =IF(科目別集計!$A12="","",科目別集計!$A12) | M2: =IF(科目別集計!$A13="","",科目別集計!$A13) | N2: =IF(科目別集計!$A14="","",科目別集計!$A14) | O2: =IF(科目別集計!$A15="","",科目別集計!$A15) | P2: =IF(科目別集計!$A16="","",科目別集計!$A16) | Q2: =IF(科目別集計!$A17="","",科目別集計!$A17) | R2: =IF(科目別集計!$A18="","",科目別集計!$A18) | S2: =IF(科目別集計!$A19="","",科目別集計!$A19) | T2: =IF(科目別集計!$A20="","",科目別集計!$A20) | U2: =IF(科目別集計!$A21="","",科目別集計!$A21) | V2: =IF(科目別集計!$A22="","",科目別集計!$A22) | W2: =IF(科目別集計!$A23="","",科目別集計!$A23) | X2: =IF(科目別集計!$A24="","",科目別集計!$A24) | Y2: =IF(科目別集計!$A25="","",科目別集計!$A25) | Z2: 備考
A3: =IF(支払先マスタ!A3="","",支払先マスタ!A3) | B3: =IF(COUNT(C3:Y3)=0,"",SUM(C3:Y3)) | C3: 228360
A4: =IF(支払先マスタ!A4="","",支払先マスタ!A4) | B4: =IF(COUNT(C4:Y4)=0,"",SUM(C4:Y4)) | C4: 382500
A5: =IF(支払先マスタ!A5="","",支払先マスタ!A5) | B5: =IF(COUNT(C5:Y5)=0,"",SUM(C5:Y5)) | C5: 350000
A6: =IF(支払先マスタ!A6="","",支払先マスタ!A6) | B6: =IF(COUNT(C6:Y6)=0,"",SUM(C6:Y6)) | C6: 390000
A7: =IF(支払先マスタ!A7="","",支払先マスタ!A7) | B7: =IF(COUNT(C7:Y7)=0,"",SUM(C7:Y7)) | C7: 60000
A8: =IF(支払先マスタ!A8="","",支払先マスタ!A8) | B8: =IF(COUNT(C8:Y8)=0,"",SUM(C8:Y8)) | C8: 170000
A9: =IF(支払先マスタ!A9="","",支払先マスタ!A9) | B9: =IF(COUNT(C9:Y9)=0,"",SUM(C9:Y9)) | C9: 165000
A10: =IF(支払先マスタ!A10="","",支払先マスタ!A10) | B10: =IF(COUNT(C10:Y10)=0,"",SUM(C10:Y10)) | C10: 55000
A11: =IF(支払先マスタ!A11="","",支払先マスタ!A11) | B11: =IF(COUNT(C11:Y11)=0,"",SUM(C11:Y11)) | C11: 35200
A12: =IF(支払先マスタ!A12="","",支払先マスタ!A12) | B12: =IF(COUNT(C12:Y12)=0,"",SUM(C12:Y12)) | C12: 29700
A13: =IF(支払先マスタ!A13="","",支払先マスタ!A13) | B13: =IF(COUNT(C13:Y13)=0,"",SUM(C13:Y13)) | C13: 90000
A14: =IF(支払先マスタ!A14="","",支払先マスタ!A14) | B14: =IF(COUNT(C14:Y14)=0,"",SUM(C14:Y14)) | C14: 67300
A15: =IF(支払先マスタ!A15="","",支払先マスタ!A15) | B15: =IF(COUNT(C15:Y15)=0,"",SUM(C15:Y15))
A16: =IF(支払先マスタ!A16="","",支払先マスタ!A16) | B16: =IF(COUNT(C16:Y16)=0,"",SUM(C16:Y16)) | D16: 322350
A17: =IF(支払先マスタ!A17="","",支払先マスタ!A17) | B17: =IF(COUNT(C17:Y17)=0,"",SUM(C17:Y17))
A18: =IF(支払先マスタ!A18="","",支払先マスタ!A18) | B18: =IF(COUNT(C18:Y18)=0,"",SUM(C18:Y18))
A19: =IF(支払先マスタ!A19="","",支払先マスタ!A19) | B19: =IF(COUNT(C19:Y19)=0,"",SUM(C19:Y19))
A20: =IF(支払先マスタ!A20="","",支払先マスタ!A20) | B20: =IF(COUNT(C20:Y20)=0,"",SUM(C20:Y20)) | E20: 288893
A21: =IF(支払先マスタ!A21="","",支払先マスタ!A21) | B21: =IF(COUNT(C21:Y21)=0,"",SUM(C21:Y21)) | E21: 550000
A22: =IF(支払先マスタ!A22="","",支払先マスタ!A22) | B22: =IF(COUNT(C22:Y22)=0,"",SUM(C22:Y22)) | E22: 103400
A23: =IF(支払先マスタ!A23="","",支払先マスタ!A23) | B23: =IF(COUNT(C23:Y23)=0,"",SUM(C23:Y23)) | E23: 123377
A24: =IF(支払先マスタ!A24="","",支払先マスタ!A24) | B24: =IF(COUNT(C24:Y24)=0,"",SUM(C24:Y24)) | F24: 60000
A25: =IF(支払先マスタ!A25="","",支払先マスタ!A25) | B25: =IF(COUNT(C25:Y25)=0,"",SUM(C25:Y25)) | F25: 89100
A26: =IF(支払先マスタ!A26="","",支払先マスタ!A26) | B26: =IF(COUNT(C26:Y26)=0,"",SUM(C26:Y26)) | F26: 31020
A27: =IF(支払先マスタ!A27="","",支払先マスタ!A27) | B27: =IF(COUNT(C27:Y27)=0,"",SUM(C27:Y27)) | F27: 23057
A28: =IF(支払先マスタ!A28="","",支払先マスタ!A28) | B28: =IF(COUNT(C28:Y28)=0,"",SUM(C28:Y28)) | F28: 231000
A29: =IF(支払先マスタ!A29="","",支払先マスタ!A29) | B29: =IF(COUNT(C29:Y29)=0,"",SUM(C29:Y29)) | G29: 82367
A30: =IF(支払先マスタ!A30="","",支払先マスタ!A30) | B30: =IF(COUNT(C30:Y30)=0,"",SUM(C30:Y30))
A31: =IF(支払先マスタ!A31="","",支払先マスタ!A31) | B31: =IF(COUNT(C31:Y31)=0,"",SUM(C31:Y31))
A32: =IF(支払先マスタ!A32="","",支払先マスタ!A32) | B32: =IF(COUNT(C32:Y32)=0,"",SUM(C32:Y32)) | I32: 18301
A33: =IF(支払先マスタ!A33="","",支払先マスタ!A33) | B33: =IF(COUNT(C33:Y33)=0,"",SUM(C33:Y33)) | J33: 1103802
A34: =IF(支払先マスタ!A34="","",支払先マスタ!A34) | B34: =IF(COUNT(C34:Y34)=0,"",SUM(C34:Y34)) | M34: 72458
A35: =IF(支払先マスタ!A35="","",支払先マスタ!A35) | B35: =IF(COUNT(C35:Y35)=0,"",SUM(C35:Y35)) | E35: 102568 | N35: 66448
A36: =IF(支払先マスタ!A36="","",支払先マスタ!A36) | B36: =IF(COUNT(C36:Y36)=0,"",SUM(C36:Y36)) | D36: 58410 | H36: 849200
A37: =IF(支払先マスタ!A37="","",支払先マスタ!A37) | B37: =IF(COUNT(C37:Y37)=0,"",SUM(C37:Y37)) | D37: 170800 | E37: 124850 | K37: 22400 | L37: 23550
A38: =IF(支払先マスタ!A38="","",支払先マスタ!A38) | B38: =IF(COUNT(C38:Y38)=0,"",SUM(C38:Y38))
A39: =IF(支払先マスタ!A39="","",支払先マスタ!A39) | B39: =IF(COUNT(C39:Y39)=0,"",SUM(C39:Y39))
A40: =IF(支払先マスタ!A40="","",支払先マスタ!A40) | B40: =IF(COUNT(C40:Y40)=0,"",SUM(C40:Y40)) | E40: 8250
...

Sheet 202608
A1: 202608（2026年8月） 支払先別 × 勘定科目 | E1: ※ 支払先の追加は「支払先マスタ」／科目の追加は「科目別集計」シートで行うと全月に反映されます
A2: 支払先 | B2: 合計 | C2: =IF(科目別集計!$A3="","",科目別集計!$A3) | D2: =IF(科目別集計!$A4="","",科目別集計!$A4) | E2: =IF(科目別集計!$A5="","",科目別集計!$A5) | F2: =IF(科目別集計!$A6="","",科目別集計!$A6) | G2: =IF(科目別集計!$A7="","",科目別集計!$A7) | H2: =IF(科目別集計!$A8="","",科目別集計!$A8) | I2: =IF(科目別集計!$A9="","",科目別集計!$A9) | J2: =IF(科目別集計!$A10="","",科目別集計!$A10) | K2: =IF(科目別集計!$A11="","",科目別集計!$A11) | L2: =IF(科目別集計!$A12="","",科目別集計!$A12) | M2: =IF(科目別集計!$A13="","",科目別集計!$A13) | N2: =IF(科目別集計!$A14="","",科目別集計!$A14) | O2: =IF(科目別集計!$A15="","",科目別集計!$A15) | P2: =IF(科目別集計!$A16="","",科目別集計!$A16) | Q2: =IF(科目別集計!$A17="","",科目別集計!$A17) | R2: =IF(科目別集計!$A18="","",科目別集計!$A18) | S2: =IF(科目別集計!$A19="","",科目別集計!$A19) | T2: =IF(科目別集計!$A20="","",科目別集計!$A20) | U2: =IF(科目別集計!$A21="","",科目別集計!$A21) | V2: =IF(科目別集計!$A22="","",科目別集計!$A22) | W2: =IF(科目別集計!$A23="","",科目別集計!$A23) | X2: =IF(科目別集計!$A24="","",科目別集計!$A24) | Y2: =IF(科目別集計!$A25="","",科目別集計!$A25) | Z2: 備考
A3: =IF(支払先マスタ!A3="","",支払先マスタ!A3) | B3: =IF(COUNT(C3:Y3)=0,"",SUM(C3:Y3)) | C3: 228360
A4: =IF(支払先マスタ!A4="","",支払先マスタ!A4) | B4: =IF(COUNT(C4:Y4)=0,"",SUM(C4:Y4)) | C4: 382500
A5: =IF(支払先マスタ!A5="","",支払先マスタ!A5) | B5: =IF(COUNT(C5:Y5)=0,"",SUM(C5:Y5)) | C5: 350000
A6: =IF(支払先マスタ!A6="","",支払先マスタ!A6) | B6: =IF(COUNT(C6:Y6)=0,"",SUM(C6:Y6)) | C6: 390000
A7: =IF(支払先マスタ!A7="","",支払先マスタ!A7) | B7: =IF(COUNT(C7:Y7)=0,"",SUM(C7:Y7)) | C7: 60000
A8: =IF(支払先マスタ!A8="","",支払先マスタ!A8) | B8: =IF(COUNT(C8:Y8)=0,"",SUM(C8:Y8)) | C8: 170000
A9: =IF(支払先マスタ!A9="","",支払先マスタ!A9) | B9: =IF(COUNT(C9:Y9)=0,"",SUM(C9:Y9)) | C9: 165000
A10: =IF(支払先マスタ!A10="","",支払先マスタ!A10) | B10: =IF(COUNT(C10:Y10)=0,"",SUM(C10:Y10)) | C10: 55000
A11: =IF(支払先マスタ!A11="","",支払先マスタ!A11) | B11: =IF(COUNT(C11:Y11)=0,"",SUM(C11:Y11)) | C11: 35200
A12: =IF(支払先マスタ!A12="","",支払先マスタ!A12) | B12: =IF(COUNT(C12:Y12)=0,"",SUM(C12:Y12)) | C12: 29700
A13: =IF(支払先マスタ!A13="","",支払先マスタ!A13) | B13: =IF(COUNT(C13:Y13)=0,"",SUM(C13:Y13)) | C13: 90000
A14: =IF(支払先マスタ!A14="","",支払先マスタ!A14) | B14: =IF(COUNT(C14:Y14)=0,"",SUM(C14:Y14)) | C14: 67300
A15: =IF(支払先マスタ!A15="","",支払先マスタ!A15) | B15: =IF(COUNT(C15:Y15)=0,"",SUM(C15:Y15)) | D15: 35310
A16: =IF(支払先マスタ!A16="","",支払先マスタ!A16) | B16: =IF(COUNT(C16:Y16)=0,"",SUM(C16:Y16)) | D16: 1649540
A17: =IF(支払先マスタ!A17="","",支払先マスタ!A17) | B17: =IF(COUNT(C17:Y17)=0,"",SUM(C17:Y17))
A18: =IF(支払先マスタ!A18="","",支払先マスタ!A18) | B18: =IF(COUNT(C18:Y18)=0,"",SUM(C18:Y18)) | D18: 485760
A19: =IF(支払先マスタ!A19="","",支払先マスタ!A19) | B19: =IF(COUNT(C19:Y19)=0,"",SUM(C19:Y19)) | D19: 286000
A20: =IF(支払先マスタ!A20="","",支払先マスタ!A20) | B20: =IF(COUNT(C20:Y20)=0,"",SUM(C20:Y20)) | E20: 461780
A21: =IF(支払先マスタ!A21="","",支払先マスタ!A21) | B21: =IF(COUNT(C21:Y21)=0,"",SUM(C21:Y21))
A22: =IF(支払先マスタ!A22="","",支払先マスタ!A22) | B22: =IF(COUNT(C22:Y22)=0,"",SUM(C22:Y22)) | E22: 155881
A23: =IF(支払先マスタ!A23="","",支払先マスタ!A23) | B23: =IF(COUNT(C23:Y23)=0,"",SUM(C23:Y23)) | E23: 151756
A24: =IF(支払先マスタ!A24="","",支払先マスタ!A24) | B24: =IF(COUNT(C24:Y24)=0,"",SUM(C24:Y24)) | F24: 60000
A25: =IF(支払先マスタ!A25="","",支払先マスタ!A25) | B25: =IF(COUNT(C25:Y25)=0,"",SUM(C25:Y25)) | F25: 89100
A26: =IF(支払先マスタ!A26="","",支払先マスタ!A26) | B26: =IF(COUNT(C26:Y26)=0,"",SUM(C26:Y26)) | F26: 31020
A27: =IF(支払先マスタ!A27="","",支払先マスタ!A27) | B27: =IF(COUNT(C27:Y27)=0,"",SUM(C27:Y27)) | F27: 20167
A28: =IF(支払先マスタ!A28="","",支払先マスタ!A28) | B28: =IF(COUNT(C28:Y28)=0,"",SUM(C28:Y28)) | F28: 66000
A29: =IF(支払先マスタ!A29="","",支払先マスタ!A29) | B29: =IF(COUNT(C29:Y29)=0,"",SUM(C29:Y29)) | G29: 72056
A30: =IF(支払先マスタ!A30="","",支払先マスタ!A30) | B30: =IF(COUNT(C30:Y30)=0,"",SUM(C30:Y30)) | G30: 2178
A31: =IF(支払先マスタ!A31="","",支払先マスタ!A31) | B31: =IF(COUNT(C31:Y31)=0,"",SUM(C31:Y31)) | G31: 9974
A32: =IF(支払先マスタ!A32="","",支払先マスタ!A32) | B32: =IF(COUNT(C32:Y32)=0,"",SUM(C32:Y32)) | I32: 14720
A33: =IF(支払先マスタ!A33="","",支払先マスタ!A33) | B33: =IF(COUNT(C33:Y33)=0,"",SUM(C33:Y33)) | J33: 477592
A34: =IF(支払先マスタ!A34="","",支払先マスタ!A34) | B34: =IF(COUNT(C34:Y34)=0,"",SUM(C34:Y34))
A35: =IF(支払先マスタ!A35="","",支払先マスタ!A35) | B35: =IF(COUNT(C35:Y35)=0,"",SUM(C35:Y35)) | E35: 160084
A36: =IF(支払先マスタ!A36="","",支払先マスタ!A36) | B36: =IF(COUNT(C36:Y36)=0,"",SUM(C36:Y36)) | D36: 129494 | H36: 849200
A37: =IF(支払先マスタ!A37="","",支払先マスタ!A37) | B37: =IF(COUNT(C37:Y37)=0,"",SUM(C37:Y37)) | D37: 339900
A38: =IF(支払先マスタ!A38="","",支払先マスタ!A38) | B38: =IF(COUNT(C38:Y38)=0,"",SUM(C38:Y38)) | D38: 56760 | K38: 17540 | L38: 8800 | O38: 7500
A39: =IF(支払先マスタ!A39="","",支払先マスタ!A39) | B39: =IF(COUNT(C39:Y39)=0,"",SUM(C39:Y39)) | D39: 46200 | E39: 14300
A40: =IF(支払先マスタ!A40="","",支払先マスタ!A40) | B40: =IF(COUNT(C40:Y40)=0,"",SUM(C40:Y40))
...

Sheet 202609
A1: 202609（2026年9月） 支払先別 × 勘定科目 | E1: ※ 支払先の追加は「支払先マスタ」／科目の追加は「科目別集計」シートで行うと全月に反映されます
A2: 支払先 | B2: 合計 | C2: =IF(科目別集計!$A3="","",科目別集計!$A3) | D2: =IF(科目別集計!$A4="","",科目別集計!$A4) | E2: =IF(科目別集計!$A5="","",科目別集計!$A5) | F2: =IF(科目別集計!$A6="","",科目別集計!$A6) | G2: =IF(科目別集計!$A7="","",科目別集計!$A7) | H2: =IF(科目別集計!$A8="","",科目別集計!$A8) | I2: =IF(科目別集計!$A9="","",科目別集計!$A9) | J2: =IF(科目別集計!$A10="","",科目別集計!$A10) | K2: =IF(科目別集計!$A11="","",科目別集計!$A11) | L2: =IF(科目別集計!$A12="","",科目別集計!$A12) | M2: =IF(科目別集計!$A13="","",科目別集計!$A13) | N2: =IF(科目別集計!$A14="","",科目別集計!$A14) | O2: =IF(科目別集計!$A15="","",科目別集計!$A15) | P2: =IF(科目別集計!$A16="","",科目別集計!$A16) | Q2: =IF(科目別集計!$A17="","",科目別集計!$A17) | R2: =IF(科目別集計!$A18="","",科目別集計!$A18) | S2: =IF(科目別集計!$A19="","",科目別集計!$A19) | T2: =IF(科目別集計!$A20="","",科目別集計!$A20) | U2: =IF(科目別集計!$A21="","",科目別集計!$A21) | V2: =IF(科目別集計!$A22="","",科目別集計!$A22) | W2: =IF(科目別集計!$A23="","",科目別集計!$A23) | X2: =IF(科目別集計!$A24="","",科目別集計!$A24) | Y2: =IF(科目別集計!$A25="","",科目別集計!$A25) | Z2: 備考
A3: =IF(支払先マスタ!A3="","",支払先マスタ!A3) | B3: =IF(COUNT(C3:Y3)=0,"",SUM(C3:Y3))
A4: =IF(支払先マスタ!A4="","",支払先マスタ!A4) | B4: =IF(COUNT(C4:Y4)=0,"",SUM(C4:Y4)) | C4: 382500
A5: =IF(支払先マスタ!A5="","",支払先マスタ!A5) | B5: =IF(COUNT(C5:Y5)=0,"",SUM(C5:Y5)) | C5: 350000
A6: =IF(支払先マスタ!A6="","",支払先マスタ!A6) | B6: =IF(COUNT(C6:Y6)=0,"",SUM(C6:Y6)) | C6: 390000
A7: =IF(支払先マスタ!A7="","",支払先マスタ!A7) | B7: =IF(COUNT(C7:Y7)=0,"",SUM(C7:Y7)) | C7: 60000
A8: =IF(支払先マスタ!A8="","",支払先マスタ!A8) | B8: =IF(COUNT(C8:Y8)=0,"",SUM(C8:Y8)) | C8: 170000
A9: =IF(支払先マスタ!A9="","",支払先マスタ!A9) | B9: =IF(COUNT(C9:Y9)=0,"",SUM(C9:Y9)) | C9: 165000
A10: =IF(支払先マスタ!A10="","",支払先マスタ!A10) | B10: =IF(COUNT(C10:Y10)=0,"",SUM(C10:Y10)) | C10: 55000
A11: =IF(支払先マスタ!A11="","",支払先マスタ!A11) | B11: =IF(COUNT(C11:Y11)=0,"",SUM(C11:Y11)) | C11: 35200
A12: =IF(支払先マスタ!A12="","",支払先マスタ!A12) | B12: =IF(COUNT(C12:Y12)=0,"",SUM(C12:Y12)) | C12: 29700
A13: =IF(支払先マスタ!A13="","",支払先マスタ!A13) | B13: =IF(COUNT(C13:Y13)=0,"",SUM(C13:Y13)) | C13: 90000
A14: =IF(支払先マスタ!A14="","",支払先マスタ!A14) | B14: =IF(COUNT(C14:Y14)=0,"",SUM(C14:Y14)) | C14: 67300
A15: =IF(支払先マスタ!A15="","",支払先マスタ!A15) | B15: =IF(COUNT(C15:Y15)=0,"",SUM(C15:Y15))
A16: =IF(支払先マスタ!A16="","",支払先マスタ!A16) | B16: =IF(COUNT(C16:Y16)=0,"",SUM(C16:Y16))
A17: =IF(支払先マスタ!A17="","",支払先マスタ!A17) | B17: =IF(COUNT(C17:Y17)=0,"",SUM(C17:Y17))
A18: =IF(支払先マスタ!A18="","",支払先マスタ!A18) | B18: =IF(COUNT(C18:Y18)=0,"",SUM(C18:Y18))
A19: =IF(支払先マスタ!A19="","",支払先マスタ!A19) | B19: =IF(COUNT(C19:Y19)=0,"",SUM(C19:Y19))
A20: =IF(支払先マスタ!A20="","",支払先マスタ!A20) | B20: =IF(COUNT(C20:Y20)=0,"",SUM(C20:Y20))
A21: =IF(支払先マスタ!A21="","",支払先マスタ!A21) | B21: =IF(COUNT(C21:Y21)=0,"",SUM(C21:Y21))
A22: =IF(支払先マスタ!A22="","",支払先マスタ!A22) | B22: =IF(COUNT(C22:Y22)=0,"",SUM(C22:Y22))
A23: =IF(支払先マスタ!A23="","",支払先マスタ!A23) | B23: =IF(COUNT(C23:Y23)=0,"",SUM(C23:Y23))
A24: =IF(支払先マスタ!A24="","",支払先マスタ!A24) | B24: =IF(COUNT(C24:Y24)=0,"",SUM(C24:Y24)) | F24: 60000
A25: =IF(支払先マスタ!A25="","",支払先マスタ!A25) | B25: =IF(COUNT(C25:Y25)=0,"",SUM(C25:Y25))
A26: =IF(支払先マスタ!A26="","",支払先マスタ!A26) | B26: =IF(COUNT(C26:Y26)=0,"",SUM(C26:Y26))
A27: =IF(支払先マスタ!A27="","",支払先マスタ!A27) | B27: =IF(COUNT(C27:Y27)=0,"",SUM(C27:Y27))
A28: =IF(支払先マスタ!A28="","",支払先マスタ!A28) | B28: =IF(COUNT(C28:Y28)=0,"",SUM(C28:Y28))
A29: =IF(支払先マスタ!A29="","",支払先マスタ!A29) | B29: =IF(COUNT(C29:Y29)=0,"",SUM(C29:Y29))
A30: =IF(支払先マスタ!A30="","",支払先マスタ!A30) | B30: =IF(COUNT(C30:Y30)=0,"",SUM(C30:Y30))
A31: =IF(支払先マスタ!A31="","",支払先マスタ!A31) | B31: =IF(COUNT(C31:Y31)=0,"",SUM(C31:Y31))
A32: =IF(支払先マスタ!A32="","",支払先マスタ!A32) | B32: =IF(COUNT(C32:Y32)=0,"",SUM(C32:Y32))
A33: =IF(支払先マスタ!A33="","",支払先マスタ!A33) | B33: =IF(COUNT(C33:Y33)=0,"",SUM(C33:Y33))
A34: =IF(支払先マスタ!A34="","",支払先マスタ!A34) | B34: =IF(COUNT(C34:Y34)=0,"",SUM(C34:Y34))
A35: =IF(支払先マスタ!A35="","",支払先マスタ!A35) | B35: =IF(COUNT(C35:Y35)=0,"",SUM(C35:Y35))
A36: =IF(支払先マスタ!A36="","",支払先マスタ!A36) | B36: =IF(COUNT(C36:Y36)=0,"",SUM(C36:Y36))
... A55: =IF(支払先マスタ!A55="","",支払先マスタ!A55) | B55: =IF(COUNT(C55:Y55)=0,"",SUM(C55:Y55))
A56: 合計 | B56: =IF(COUNT(B3:B55)=0,"",SUM(B3:B55)) | C56: =IF(COUNT(C3:C55)=0,"",SUM(C3:C55)) | D56: =IF(COUNT(D3:D55)=0,"",SUM(D3:D55)) | E56: =IF(COUNT(E3:E55)=0,"",SUM(E3:E55)) | F56: =IF(COUNT(F3:F55)=0,"",SUM(F3:F55)) | G56: =IF(COUNT(G3:G55)=0,"",SUM(G3:G55)) | H56: =IF(COUNT(H3:H55)=0,"",SUM(H3:H55)) | I56: =IF(COUNT(I3:I55)=0,"",SUM(I3:I55)) | ... Y56: =IF(COUNT(Y3:Y55)=0,"",SUM(Y3:Y55))

Sheet 202610
A1: 202610（2026年10月） 支払先別 × 勘定科目 | E1: ※ 支払先の追加は「支払先マスタ」／科目の追加は「科目別集計」シートで行うと全月に反映されます
A2: 支払先 | B2: 合計 | C2: =IF(科目別集計!$A3="","",科目別集計!$A3) | D2: =IF(科目別集計!$A4="","",科目別集計!$A4) | E2: =IF(科目別集計!$A5="","",科目別集計!$A5) | F2: =IF(科目別集計!$A6="","",科目別集計!$A6) | G2: =IF(科目別集計!$A7="","",科目別集計!$A7) | H2: =IF(科目別集計!$A8="","",科目別集計!$A8) | I2: =IF(科目別集計!$A9="","",科目別集計!$A9) | J2: =IF(科目別集計!$A10="","",科目別集計!$A10) | K2: =IF(科目別集計!$A11="","",科目別集計!$A11) | L2: =IF(科目別集計!$A12="","",科目別集計!$A12) | M2: =IF(科目別集計!$A13="","",科目別集計!$A13) | N2: =IF(科目別集計!$A14="","",科目別集計!$A14) | O2: =IF(科目別集計!$A15="","",科目別集計!$A15) | P2: =IF(科目別集計!$A16="","",科目別集計!$A16) | Q2: =IF(科目別集計!$A17="","",科目別集計!$A17) | R2: =IF(科目別集計!$A18="","",科目別集計!$A18) | S2: =IF(科目別集計!$A19="","",科目別集計!$A19) | T2: =IF(科目別集計!$A20="","",科目別集計!$A20) | U2: =IF(科目別集計!$A21="","",科目別集計!$A21) | V2: =IF(科目別集計!$A22="","",科目別集計!$A22) | W2: =IF(科目別集計!$A23="","",科目別集計!$A23) | X2: =IF(科目別集計!$A24="","",科目別集計!$A24) | Y2: =IF(科目別集計!$A25="","",科目別集計!$A25) | Z2: 備考
A3: =IF(支払先マスタ!A3="","",支払先マスタ!A3) | B3: =IF(COUNT(C3:Y3)=0,"",SUM(C3:Y3))
A4: =IF(支払先マスタ!A4="","",支払先マスタ!A4) | B4: =IF(COUNT(C4:Y4)=0,"",SUM(C4:Y4))
A5: =IF(支払先マスタ!A5="","",支払先マスタ!A5) | B5: =IF(COUNT(C5:Y5)=0,"",SUM(C5:Y5))
A6: =IF(支払先マスタ!A6="","",支払先マスタ!A6) | B6: =IF(COUNT(C6:Y6)=0,"",SUM(C6:Y6))
A7: =IF(支払先マスタ!A7="","",支払先マスタ!A7) | B7: =IF(COUNT(C7:Y7)=0,"",SUM(C7:Y7))
A8: =IF(支払先マスタ!A8="","",支払先マスタ!A8) | B8: =IF(COUNT(C8:Y8)=0,"",SUM(C8:Y8))
A9: =IF(支払先マスタ!A9="","",支払先マスタ!A9) | B9: =IF(COUNT(C9:Y9)=0,"",SUM(C9:Y9))
A10: =IF(支払先マスタ!A10="","",支払先マスタ!A10) | B10: =IF(COUNT(C10:Y10)=0,"",SUM(C10:Y10))
A11: =IF(支払先マスタ!A11="","",支払先マスタ!A11) | B11: =IF(COUNT(C11:Y11)=0,"",SUM(C11:Y11))
A12: =IF(支払先マスタ!A12="","",支払先マスタ!A12) | B12: =IF(COUNT(C12:Y12)=0,"",SUM(C12:Y12))
A13: =IF(支払先マスタ!A13="","",支払先マスタ!A13) | B13: =IF(COUNT(C13:Y13)=0,"",SUM(C13:Y13))
A14: =IF(支払先マスタ!A14="","",支払先マスタ!A14) | B14: =IF(COUNT(C14:Y14)=0,"",SUM(C14:Y14))
... A55: =IF(支払先マスタ!A55="","",支払先マスタ!A55) | B55: =IF(COUNT(C55:Y55)=0,"",SUM(C55:Y55))
A56: 合計 | B56: =IF(COUNT(B3:B55)=0,"",SUM(B3:B55)) | C56: =IF(COUNT(C3:C55)=0,"",SUM(C3:C55)) | D56: =IF(COUNT(D3:D55)=0,"",SUM(D3:D55)) | E56: =IF(COUNT(E3:E55)=0,"",SUM(E3:E55)) | F56: =IF(COUNT(F3:F55)=0,"",SUM(F3:F55)) | G56: =IF(COUNT(G3:G55)=0,"",SUM(G3:G55)) | H56: =IF(COUNT(H3:H55)=0,"",SUM(H3:H55)) | I56: =IF(COUNT(I3:I55)=0,"",SUM(I3:I55)) | ... Y56: =IF(COUNT(Y3:Y55)=0,"",SUM(Y3:Y55))

Sheet 202611
A1: 202611（2026年11月） 支払先別 × 勘定科目 | E1: ※ 支払先の追加は「支払先マスタ」／科目の追加は「科目別集計」シートで行うと全月に反映されます
A2: 支払先 | B2: 合計 | C2: =IF(科目別集計!$A3="","",科目別集計!$A3) | D2: =IF(科目別集計!$A4="","",科目別集計!$A4) | E2: =IF(科目別集計!$A5="","",科目別集計!$A5) | F2: =IF(科目別集計!$A6="","",科目別集計!$A6) | G2: =IF(科目別集計!$A7="","",科目別集計!$A7) | H2: =IF(科目別集計!$A8="","",科目別集計!$A8) | I2: =IF(科目別集計!$A9="","",科目別集計!$A9) | J2: =IF(科目別集計!$A10="","",科目別集計!$A10) | K2: =IF(科目別集計!$A11="","",科目別集計!$A11) | L2: =IF(科目別集計!$A12="","",科目別集計!$A12) | M2: =IF(科目別集計!$A13="","",科目別集計!$A13) | N2: =IF(科目別集計!$A14="","",科目別集計!$A14) | O2: =IF(科目別集計!$A15="","",科目別集計!$A15) | P2: =IF(科目別集計!$A16="","",科目別集計!$A16) | Q2: =IF(科目別集計!$A17="","",科目別集計!$A17) | R2: =IF(科目別集計!$A18="","",科目別集計!$A18) | S2: =IF(科目別集計!$A19="","",科目別集計!$A19) | T2: =IF(科目別集計!$A20="","",科目別集計!$A20) | U2: =IF(科目別集計!$A21="","",科目別集計!$A21) | V2: =IF(科目別集計!$A22="","",科目別集計!$A22) | W2: =IF(科目別集計!$A23="","",科目別集計!$A23) | X2: =IF(科目別集計!$A24="","",科目別集計!$A24) | Y2: =IF(科目別集計!$A25="","",科目別集計!$A25) | Z2: 備考
A3: =IF(支払先マスタ!A3="","",支払先マスタ!A3) | B3: =IF(COUNT(C3:Y3)=0,"",SUM(C3:Y3))
A4: =IF(支払先マスタ!A4="","",支払先マスタ!A4) | B4: =IF(COUNT(C4:Y4)=0,"",SUM(C4:Y4))
A5: =IF(支払先マスタ!A5="","",支払先マスタ!A5) | B5: =IF(COUNT(C5:Y5)=0,"",SUM(C5:Y5))
A6: =IF(支払先マスタ!A6="","",支払先マスタ!A6) | B6: =IF(COUNT(C6:Y6)=0,"",SUM(C6:Y6))
A7: =IF(支払先マスタ!A7="","",支払先マスタ!A7) | B7: =IF(COUNT(C7:Y7)=0,"",SUM(C7:Y7))
A8: =IF(支払先マスタ!A8="","",支払先マスタ!A8) | B8: =IF(COUNT(C8:Y8)=0,"",SUM(C8:Y8))
A9: =IF(支払先マスタ!A9="","",支払先マスタ!A9) | B9: =IF(COUNT(C9:Y9)=0,"",SUM(C9:Y9))
A10: =IF(支払先マスタ!A10="","",支払先マスタ!A10) | B10: =IF(COUNT(C10:Y10)=0,"",SUM(C10:Y10))
A11: =IF(支払先マスタ!A11="","",支払先マスタ!A11) | B11: =IF(COUNT(C11:Y11)=0,"",SUM(C11:Y11))
A12: =IF(支払先マスタ!A12="","",支払先マスタ!A12) | B12: =IF(COUNT(C12:Y12)=0,"",SUM(C12:Y12))
A13: =IF(支払先マスタ!A13="","",支払先マスタ!A13) | B13: =IF(COUNT(C13:Y13)=0,"",SUM(C13:Y13))
A14: =IF(支払先マスタ!A14="","",支払先マスタ!A14) | B14: =IF(COUNT(C14:Y14)=0,"",SUM(C14:Y14))
... A55: =IF(支払先マスタ!A55="","",支払先マスタ!A55) | B55: =IF(COUNT(C55:Y55)=0,"",SUM(C55:Y55))
A56: 合計 | B56: =IF(COUNT(B3:B55)=0,"",SUM(B3:B55)) | C56: =IF(COUNT(C3:C55)=0,"",SUM(C3:C55)) | D56: =IF(COUNT(D3:D55)=0,"",SUM(D3:D55)) | E56: =IF(COUNT(E3:E55)=0,"",SUM(E3:E55)) | F56: =IF(COUNT(F3:F55)=0,"",SUM(F3:F55)) | G56: =IF(COUNT(G3:G55)=0,"",SUM(G3:G55)) | H56: =IF(COUNT(H3:H55)=0,"",SUM(H3:H55)) | I56: =IF(COUNT(I3:I55)=0,"",SUM(I3:I55)) | ... Y56: =IF(COUNT(Y3:Y55)=0,"",SUM(Y3:Y55))

Sheet 202612
A1: 202612（2026年12月） 支払先別 × 勘定科目 | E1: ※ 支払先の追加は「支払先マスタ」／科目の追加は「科目別集計」シートで行うと全月に反映されます
A2: 支払先 | B2: 合計 | C2: =IF(科目別集計!$A3="","",科目別集計!$A3) | D2: =IF(科目別集計!$A4="","",科目別集計!$A4) | E2: =IF(科目別集計!$A5="","",科目別集計!$A5) | F2: =IF(科目別集計!$A6="","",科目別集計!$A6) | G2: =IF(科目別集計!$A7="","",科目別集計!$A7) | H2: =IF(科目別集計!$A8="","",科目別集計!$A8) | I2: =IF(科目別集計!$A9="","",科目別集計!$A9) | J2: =IF(科目別集計!$A10="","",科目別集計!$A10) | K2: =IF(科目別集計!$A11="","",科目別集計!$A11) | L2: =IF(科目別集計!$A12="","",科目別集計!$A12) | M2: =IF(科目別集計!$A13="","",科目別集計!$A13) | N2: =IF(科目別集計!$A14="","",科目別集計!$A14) | O2: =IF(科目別集計!$A15="","",科目別集計!$A15) | P2: =IF(科目別集計!$A16="","",科目別集計!$A16) | Q2: =IF(科目別集計!$A17="","",科目別集計!$A17) | R2: =IF(科目別集計!$A18="","",科目別集計!$A18) | S2: =IF(科目別集計!$A19="","",科目別集計!$A19) | T2: =IF(科目別集計!$A20="","",科目別集計!$A20) | U2: =IF(科目別集計!$A21="","",科目別集計!$A21) | V2: =IF(科目別集計!$A22="","",科目別集計!$A22) | W2: =IF(科目別集計!$A23="","",科目別集計!$A23) | X2: =IF(科目別集計!$A24="","",科目別集計!$A24) | Y2: =IF(科目別集計!$A25="","",科目別集計!$A25) | Z2: 備考
A3: =IF(支払先マスタ!A3="","",支払先マスタ!A3) | B3: =IF(COUNT(C3:Y3)=0,"",SUM(C3:Y3))
A4: =IF(支払先マスタ!A4="","",支払先マスタ!A4) | B4: =IF(COUNT(C4:Y4)=0,"",SUM(C4:Y4))
A5: =IF(支払先マスタ!A5="","",支払先マスタ!A5) | B5: =IF(COUNT(C5:Y5)=0,"",SUM(C5:Y5))
A6: =IF(支払先マスタ!A6="","",支払先マスタ!A6) | B6: =IF(COUNT(C6:Y6)=0,"",SUM(C6:Y6))
A7: =IF(支払先マスタ!A7="","",支払先マスタ!A7) | B7: =IF(COUNT(C7:Y7)=0,"",SUM(C7:Y7))
A8: =IF(支払先マスタ!A8="","",支払先マスタ!A8) | B8: =IF(COUNT(C8:Y8)=0,"",SUM(C8:Y8))
A9: =IF(支払先マスタ!A9="","",支払先マスタ!A9) | B9: =IF(COUNT(C9:Y9)=0,"",SUM(C9:Y9))
A10: =IF(支払先マスタ!A10="","",支払先マスタ!A10) | B10: =IF(COUNT(C10:Y10)=0,"",SUM(C10:Y10))
A11: =IF(支払先マスタ!A11="","",支払先マスタ!A11) | B11: =IF(COUNT(C11:Y11)=0,"",SUM(C11:Y11))
A12: =IF(支払先マスタ!A12="","",支払先マスタ!A12) | B12: =IF(COUNT(C12:Y12)=0,"",SUM(C12:Y12))
A13: =IF(支払先マスタ!A13="","",支払先マスタ!A13) | B13: =IF(COUNT(C13:Y13)=0,"",SUM(C13:Y13))
A14: =IF(支払先マスタ!A14="","",支払先マスタ!A14) | B14: =IF(COUNT(C14:Y14)=0,"",SUM(C14:Y14))
... A55: =IF(支払先マスタ!A55="","",支払先マスタ!A55) | B55: =IF(COUNT(C55:Y55)=0,"",SUM(C55:Y55))
A56: 合計 | B56: =IF(COUNT(B3:B55)=0,"",SUM(B3:B55)) | C56: =IF(COUNT(C3:C55)=0,"",SUM(C3:C55)) | D56: =IF(COUNT(D3:D55)=0,"",SUM(D3:D55)) | E56: =IF(COUNT(E3:E55)=0,"",SUM(E3:E55)) | F56: =IF(COUNT(F3:F55)=0,"",SUM(F3:F55)) | G56: =IF(COUNT(G3:G55)=0,"",SUM(G3:G55)) | H56: =IF(COUNT(H3:H55)=0,"",SUM(H3:H55)) | I56: =IF(COUNT(I3:I55)=0,"",SUM(I3:I55)) | ... Y56: =IF(COUNT(Y3:Y55)=0,"",SUM(Y3:Y55))

Sheet 202701
A1: 202701（2027年1月） 支払先別 × 勘定科目 | E1: ※ 支払先の追加は「支払先マスタ」／科目の追加は「科目別集計」シートで行うと全月に反映されます
A2: 支払先 | B2: 合計 | C2: =IF(科目別集計!$A3="","",科目別集計!$A3) | D2: =IF(科目別集計!$A4="","",科目別集計!$A4) | E2: =IF(科目別集計!$A5="","",科目別集計!$A5) | F2: =IF(科目別集計!$A6="","",科目別集計!$A6) | G2: =IF(科目別集計!$A7="","",科目別集計!$A7) | H2: =IF(科目別集計!$A8="","",科目別集計!$A8) | I2: =IF(科目別集計!$A9="","",科目別集計!$A9) | J2: =IF(科目別集計!$A10="","",科目別集計!$A10) | K2: =IF(科目別集計!$A11="","",科目別集計!$A11) | L2: =IF(科目別集計!$A12="","",科目別集計!$A12) | M2: =IF(科目別集計!$A13="","",科目別集計!$A13) | N2: =IF(科目別集計!$A14="","",科目別集計!$A14) | O2: =IF(科目別集計!$A15="","",科目別集計!$A15) | P2: =IF(科目別集計!$A16="","",科目別集計!$A16) | Q2: =IF(科目別集計!$A17="","",科目別集計!$A17) | R2: =IF(科目別集計!$A18="","",科目別集計!$A18) | S2: =IF(科目別集計!$A19="","",科目別集計!$A19) | T2: =IF(科目別集計!$A20="","",科目別集計!$A20) | U2: =IF(科目別集計!$A21="","",科目別集計!$A21) | V2: =IF(科目別集計!$A22="","",科目別集計!$A22) | W2: =IF(科目別集計!$A23="","",科目別集計!$A23) | X2: =IF(科目別集計!$A24="","",科目別集計!$A24) | Y2: =IF(科目別集計!$A25="","",科目別集計!$A25) | Z2: 備考
A3: =IF(支払先マスタ!A3="","",支払先マスタ!A3) | B3: =IF(COUNT(C3:Y3)=0,"",SUM(C3:Y3))
A4: =IF(支払先マスタ!A4="","",支払先マスタ!A4) | B4: =IF(COUNT(C4:Y4)=0,"",SUM(C4:Y4))
A5: =IF(支払先マスタ!A5="","",支払先マスタ!A5) | B5: =IF(COUNT(C5:Y5)=0,"",SUM(C5:Y5))
A6: =IF(支払先マスタ!A6="","",支払先マスタ!A6) | B6: =IF(COUNT(C6:Y6)=0,"",SUM(C6:Y6))
A7: =IF(支払先マスタ!A7="","",支払先マスタ!A7) | B7: =IF(COUNT(C7:Y7)=0,"",SUM(C7:Y7))
A8: =IF(支払先マスタ!A8="","",支払先マスタ!A8) | B8: =IF(COUNT(C8:Y8)=0,"",SUM(C8:Y8))
A9: =IF(支払先マスタ!A9="","",支払先マスタ!A9) | B9: =IF(COUNT(C9:Y9)=0,"",SUM(C9:Y9))
A10: =IF(支払先マスタ!A10="","",支払先マスタ!A10) | B10: =IF(COUNT(C10:Y10)=0,"",SUM(C10:Y10))
A11: =IF(支払先マスタ!A11="","",支払先マスタ!A11) | B11: =IF(COUNT(C11:Y11)=0,"",SUM(C11:Y11))
A12: =IF(支払先マスタ!A12="","",支払先マスタ!A12) | B12: =IF(COUNT(C12:Y12)=0,"",SUM(C12:Y12))
A13: =IF(支払先マスタ!A13="","",支払先マスタ!A13) | B13: =IF(COUNT(C13:Y13)=0,"",SUM(C13:Y13))
A14: =IF(支払先マスタ!A14="","",支払先マスタ!A14) | B14: =IF(COUNT(C14:Y14)=0,"",SUM(C14:Y14))
... A55: =IF(支払先マスタ!A55="","",支払先マスタ!A55) | B55: =IF(COUNT(C55:Y55)=0,"",SUM(C55:Y55))
A56: 合計 | B56: =IF(COUNT(B3:B55)=0,"",SUM(B3:B55)) | C56: =IF(COUNT(C3:C55)=0,"",SUM(C3:C55)) | D56: =IF(COUNT(D3:D55)=0,"",SUM(D3:D55)) | E56: =IF(COUNT(E3:E55)=0,"",SUM(E3:E55)) | F56: =IF(COUNT(F3:F55)=0,"",SUM(F3:F55)) | G56: =IF(COUNT(G3:G55)=0,"",SUM(G3:G55)) | H56: =IF(COUNT(H3:H55)=0,"",SUM(H3:H55)) | I56: =IF(COUNT(I3:I55)=0,"",SUM(I3:I55)) | ... Y56: =IF(COUNT(Y3:Y55)=0,"",SUM(Y3:Y55))

Sheet 202702
A1: 202702（2027年2月） 支払先別 × 勘定科目 | E1: ※ 支払先の追加は「支払先マスタ」／科目の追加は「科目別集計」シートで行うと全月に反映されます
A2: 支払先 | B2: 合計 | C2: =IF(科目別集計!$A3="","",科目別集計!$A3) | D2: =IF(科目別集計!$A4="","",科目別集計!$A4) | E2: =IF(科目別集計!$A5="","",科目別集計!$A5) | F2: =IF(科目別集計!$A6="","",科目別集計!$A6) | G2: =IF(科目別集計!$A7="","",科目別集計!$A7) | H2: =IF(科目別集計!$A8="","",科目別集計!$A8) | I2: =IF(科目別集計!$A9="","",科目別集計!$A9) | J2: =IF(科目別集計!$A10="","",科目別集計!$A10) | K2: =IF(科目別集計!$A11="","",科目別集計!$A11) | L2: =IF(科目別集計!$A12="","",科目別集計!$A12) | M2: =IF(科目別集計!$A13="","",科目別集計!$A13) | N2: =IF(科目別集計!$A14="","",科目別集計!$A14) | O2: =IF(科目別集計!$A15="","",科目別集計!$A15) | P2: =IF(科目別集計!$A16="","",科目別集計!$A16) | Q2: =IF(科目別集計!$A17="","",科目別集計!$A17) | R2: =IF(科目別集計!$A18="","",科目別集計!$A18) | S2: =IF(科目別集計!$A19="","",科目別集計!$A19) | T2: =IF(科目別集計!$A20="","",科目別集計!$A20) | U2: =IF(科目別集計!$A21="","",科目別集計!$A21) | V2: =IF(科目別集計!$A22="","",科目別集計!$A22) | W2: =IF(科目別集計!$A23="","",科目別集計!$A23) | X2: =IF(科目別集計!$A24="","",科目別集計!$A24) | Y2: =IF(科目別集計!$A25="","",科目別集計!$A25) | Z2: 備考
A3: =IF(支払先マスタ!A3="","",支払先マスタ!A3) | B3: =IF(COUNT(C3:Y3)=0,"",SUM(C3:Y3))
A4: =IF(支払先マスタ!A4="","",支払先マスタ!A4) | B4: =IF(COUNT(C4:Y4)=0,"",SUM(C4:Y4))
A5: =IF(支払先マスタ!A5="","",支払先マスタ!A5) | B5: =IF(COUNT(C5:Y5)=0,"",SUM(C5:Y5))
A6: =IF(支払先マスタ!A6="","",支払先マスタ!A6) | B6: =IF(COUNT(C6:Y6)=0,"",SUM(C6:Y6))
A7: =IF(支払先マスタ!A7="","",支払先マスタ!A7) | B7: =IF(COUNT(C7:Y7)=0,"",SUM(C7:Y7))
A8: =IF(支払先マスタ!A8="","",支払先マスタ!A8) | B8: =IF(COUNT(C8:Y8)=0,"",SUM(C8:Y8))
A9: =IF(支払先マスタ!A9="","",支払先マスタ!A9) | B9: =IF(COUNT(C9:Y9)=0,"",SUM(C9:Y9))
A10: =IF(支払先マスタ!A10="","",支払先マスタ!A10) | B10: =IF(COUNT(C10:Y10)=0,"",SUM(C10:Y10))
A11: =IF(支払先マスタ!A11="","",支払先マスタ!A11) | B11: =IF(COUNT(C11:Y11)=0,"",SUM(C11:Y11))
A12: =IF(支払先マスタ!A12="","",支払先マスタ!A12) | B12: =IF(COUNT(C12:Y12)=0,"",SUM(C12:Y12))
A13: =IF(支払先マスタ!A13="","",支払先マスタ!A13) | B13: =IF(COUNT(C13:Y13)=0,"",SUM(C13:Y13))
A14: =IF(支払先マスタ!A14="","",支払先マスタ!A14) | B14: =IF(COUNT(C14:Y14)=0,"",SUM(C14:Y14))
... A55: =IF(支払先マスタ!A55="","",支払先マスタ!A55) | B55: =IF(COUNT(C55:Y55)=0,"",SUM(C55:Y55))
A56: 合計 | B56: =IF(COUNT(B3:B55)=0,"",SUM(B3:B55)) | C56: =IF(COUNT(C3:C55)=0,"",SUM(C3:C55)) | D56: =IF(COUNT(D3:D55)=0,"",SUM(D3:D55)) | E56: =IF(COUNT(E3:E55)=0,"",SUM(E3:E55)) | F56: =IF(COUNT(F3:F55)=0,"",SUM(F3:F55)) | G56: =IF(COUNT(G3:G55)=0,"",SUM(G3:G55)) | H56: =IF(COUNT(H3:H55)=0,"",SUM(H3:H55)) | I56: =IF(COUNT(I3:I55)=0,"",SUM(I3:I55)) | ... Y56: =IF(COUNT(Y3:Y55)=0,"",SUM(Y3:Y55))

Sheet 202703
A1: 202703（2027年3月） 支払先別 × 勘定科目 | E1: ※ 支払先の追加は「支払先マスタ」／科目の追加は「科目別集計」シートで行うと全月に反映されます
A2: 支払先 | B2: 合計 | C2: =IF(科目別集計!$A3="","",科目別集計!$A3) | D2: =IF(科目別集計!$A4="","",科目別集計!$A4) | E2: =IF(科目別集計!$A5="","",科目別集計!$A5) | F2: =IF(科目別集計!$A6="","",科目別集計!$A6) | G2: =IF(科目別集計!$A7="","",科目別集計!$A7) | H2: =IF(科目別集計!$A8="","",科目別集計!$A8) | I2: =IF(科目別集計!$A9="","",科目別集計!$A9) | J2: =IF(科目別集計!$A10="","",科目別集計!$A10) | K2: =IF(科目別集計!$A11="","",科目別集計!$A11) | L2: =IF(科目別集計!$A12="","",科目別集計!$A12) | M2: =IF(科目別集計!$A13="","",科目別集計!$A13) | N2: =IF(科目別集計!$A14="","",科目別集計!$A14) | O2: =IF(科目別集計!$A15="","",科目別集計!$A15) | P2: =IF(科目別集計!$A16="","",科目別集計!$A16) | Q2: =IF(科目別集計!$A17="","",科目別集計!$A17) | R2: =IF(科目別集計!$A18="","",科目別集計!$A18) | S2: =IF(科目別集計!$A19="","",科目別集計!$A19) | T2: =IF(科目別集計!$A20="","",科目別集計!$A20) | U2: =IF(科目別集計!$A21="","",科目別集計!$A21) | V2: =IF(科目別集計!$A22="","",科目別集計!$A22) | W2: =IF(科目別集計!$A23="","",科目別集計!$A23) | X2: =IF(科目別集計!$A24="","",科目別集計!$A24) | Y2: =IF(科目別集計!$A25="","",科目別集計!$A25) | Z2: 備考
A3: =IF(支払先マスタ!A3="","",支払先マスタ!A3) | B3: =IF(COUNT(C3:Y3)=0,"",SUM(C3:Y3))
A4: =IF(支払先マスタ!A4="","",支払先マスタ!A4) | B4: =IF(COUNT(C4:Y4)=0,"",SUM(C4:Y4))
A5: =IF(支払先マスタ!A5="","",支払先マスタ!A5) | B5: =IF(COUNT(C5:Y5)=0,"",SUM(C5:Y5))
A6: =IF(支払先マスタ!A6="","",支払先マスタ!A6) | B6: =IF(COUNT(C6:Y6)=0,"",SUM(C6:Y6))
A7: =IF(支払先マスタ!A7="","",支払先マスタ!A7) | B7: =IF(COUNT(C7:Y7)=0,"",SUM(C7:Y7))
A8: =IF(支払先マスタ!A8="","",支払先マスタ!A8) | B8: =IF(COUNT(C8:Y8)=0,"",SUM(C8:Y8))
A9: =IF(支払先マスタ!A9="","",支払先マスタ!A9) | B9: =IF(COUNT(C9:Y9)=0,"",SUM(C9:Y9))
A10: =IF(支払先マスタ!A10="","",支払先マスタ!A10) | B10: =IF(COUNT(C10:Y10)=0,"",SUM(C10:Y10))
A11: =IF(支払先マスタ!A11="","",支払先マスタ!A11) | B11: =IF(COUNT(C11:Y11)=0,"",SUM(C11:Y11))
A12: =IF(支払先マスタ!A12="","",支払先マスタ!A12) | B12: =IF(COUNT(C12:Y12)=0,"",SUM(C12:Y12))
A13: =IF(支払先マスタ!A13="","",支払先マスタ!A13) | B13: =IF(COUNT(C13:Y13)=0,"",SUM(C13:Y13))
A14: =IF(支払先マスタ!A14="","",支払先マスタ!A14) | B14: =IF(COUNT(C14:Y14)=0,"",SUM(C14:Y14))
... A55: =IF(支払先マスタ!A55="","",支払先マスタ!A55) | B55: =IF(COUNT(C55:Y55)=0,"",SUM(C55:Y55))
A56: 合計 | B56: =IF(COUNT(B3:B55)=0,"",SUM(B3:B55)) | C56: =IF(COUNT(C3:C55)=0,"",SUM(C3:C55)) | D56: =IF(COUNT(D3:D55)=0,"",SUM(D3:D55)) | E56: =IF(COUNT(E3:E55)=0,"",SUM(E3:E55)) | F56: =IF(COUNT(F3:F55)=0,"",SUM(F3:F55)) | G56: =IF(COUNT(G3:G55)=0,"",SUM(G3:G55)) | H56: =IF(COUNT(H3:H55)=0,"",SUM(H3:H55)) | I56: =IF(COUNT(I3:I55)=0,"",SUM(I3:I55)) | ... Y56: =IF(COUNT(Y3:Y55)=0,"",SUM(Y3:Y55))

Sheet 202704
A1: 202704（2027年4月） 支払先別 × 勘定科目 | E1: ※ 支払先の追加は「支払先マスタ」／科目の追加は「科目別集計」シートで行うと全月に反映されます
A2: 支払先 | B2: 合計 | C2: =IF(科目別集計!$A3="","",科目別集計!$A3) | D2: =IF(科目別集計!$A4="","",科目別集計!$A4) | E2: =IF(科目別集計!$A5="","",科目別集計!$A5) | F2: =IF(科目別集計!$A6="","",科目別集計!$A6) | G2: =IF(科目別集計!$A7="","",科目別集計!$A7) | H2: =IF(科目別集計!$A8="","",科目別集計!$A8) | I2: =IF(科目別集計!$A9="","",科目別集計!$A9) | J2: =IF(科目別集計!$A10="","",科目別集計!$A10) | K2: =IF(科目別集計!$A11="","",科目別集計!$A11) | L2: =IF(科目別集計!$A12="","",科目別集計!$A12) | M2: =IF(科目別集計!$A13="","",科目別集計!$A13) | N2: =IF(科目別集計!$A14="","",科目別集計!$A14) | O2: =IF(科目別集計!$A15="","",科目別集計!$A15) | P2: =IF(科目別集計!$A16="","",科目別集計!$A16) | Q2: =IF(科目別集計!$A17="","",科目別集計!$A17) | R2: =IF(科目別集計!$A18="","",科目別集計!$A18) | S2: =IF(科目別集計!$A19="","",科目別集計!$A19) | T2: =IF(科目別集計!$A20="","",科目別集計!$A20) | U2: =IF(科目別集計!$A21="","",科目別集計!$A21) | V2: =IF(科目別集計!$A22="","",科目別集計!$A22) | W2: =IF(科目別集計!$A23="","",科目別集計!$A23) | X2: =IF(科目別集計!$A24="","",科目別集計!$A24) | Y2: =IF(科目別集計!$A25="","",科目別集計!$A25) | Z2: 備考
A3: =IF(支払先マスタ!A3="","",支払先マスタ!A3) | B3: =IF(COUNT(C3:Y3)=0,"",SUM(C3:Y3))
A4: =IF(支払先マスタ!A4="","",支払先マスタ!A4) | B4: =IF(COUNT(C4:Y4)=0,"",SUM(C4:Y4))
A5: =IF(支払先マスタ!A5="","",支払先マスタ!A5) | B5: =IF(COUNT(C5:Y5)=0,"",SUM(C5:Y5))
A6: =IF(支払先マスタ!A6="","",支払先マスタ!A6) | B6: =IF(COUNT(C6:Y6)=0,"",SUM(C6:Y6))
A7: =IF(支払先マスタ!A7="","",支払先マスタ!A7) | B7: =IF(COUNT(C7:Y7)=0,"",SUM(C7:Y7))
A8: =IF(支払先マスタ!A8="","",支払先マスタ!A8) | B8: =IF(COUNT(C8:Y8)=0,"",SUM(C8:Y8))
A9: =IF(支払先マスタ!A9="","",支払先マスタ!A9) | B9: =IF(COUNT(C9:Y9)=0,"",SUM(C9:Y9))
A10: =IF(支払先マスタ!A10="","",支払先マスタ!A10) | B10: =IF(COUNT(C10:Y10)=0,"",SUM(C10:Y10))
A11: =IF(支払先マスタ!A11="","",支払先マスタ!A11) | B11: =IF(COUNT(C11:Y11)=0,"",SUM(C11:Y11))
A12: =IF(支払先マスタ!A12="","",支払先マスタ!A12) | B12: =IF(COUNT(C12:Y12)=0,"",SUM(C12:Y12))
A13: =IF(支払先マスタ!A13="","",支払先マスタ!A13) | B13: =IF(COUNT(C13:Y13)=0,"",SUM(C13:Y13))
A14: =IF(支払先マスタ!A14="","",支払先マスタ!A14) | B14: =IF(COUNT(C14:Y14)=0,"",SUM(C14:Y14))
... A55: =IF(支払先マスタ!A55="","",支払先マスタ!A55) | B55: =IF(COUNT(C55:Y55)=0,"",SUM(C55:Y55))
A56: 合計 | B56: =IF(COUNT(B3:B55)=0,"",SUM(B3:B55)) | C56: =IF(COUNT(C3:C55)=0,"",SUM(C3:C55)) | D56: =IF(COUNT(D3:D55)=0,"",SUM(D3:D55)) | E56: =IF(COUNT(E3:E55)=0,"",SUM(E3:E55)) | F56: =IF(COUNT(F3:F55)=0,"",SUM(F3:F55)) | G56: =IF(COUNT(G3:G55)=0,"",SUM(G3:G55)) | H56: =IF(COUNT(H3:H55)=0,"",SUM(H3:H55)) | I56: =IF(COUNT(I3:I55)=0,"",SUM(I3:I55)) | ... Y56: =IF(COUNT(Y3:Y55)=0,"",SUM(Y3:Y55))

Sheet 202705
A1: 202705（2027年5月） 支払先別 × 勘定科目 | E1: ※ 支払先の追加は「支払先マスタ」／科目の追加は「科目別集計」シートで行うと全月に反映されます
A2: 支払先 | B2: 合計 | C2: =IF(科目別集計!$A3="","",科目別集計!$A3) | D2: =IF(科目別集計!$A4="","",科目別集計!$A4) | E2: =IF(科目別集計!$A5="","",科目別集計!$A5) | F2: =IF(科目別集計!$A6="","",科目別集計!$A6) | G2: =IF(科目別集計!$A7="","",科目別集計!$A7) | H2: =IF(科目別集計!$A8="","",科目別集計!$A8) | I2: =IF(科目別集計!$A9="","",科目別集計!$A9) | J2: =IF(科目別集計!$A10="","",科目別集計!$A10) | K2: =IF(科目別集計!$A11="","",科目別集計!$A11) | L2: =IF(科目別集計!$A12="","",科目別集計!$A12) | M2: =IF(科目別集計!$A13="","",科目別集計!$A13) | N2: =IF(科目別集計!$A14="","",科目別集計!$A14) | O2: =IF(科目別集計!$A15="","",科目別集計!$A15) | P2: =IF(科目別集計!$A16="","",科目別集計!$A16) | Q2: =IF(科目別集計!$A17="","",科目別集計!$A17) | R2: =IF(科目別集計!$A18="","",科目別集計!$A18) | S2: =IF(科目別集計!$A19="","",科目別集計!$A19) | T2: =IF(科目別集計!$A20="","",科目別集計!$A20) | U2: =IF(科目別集計!$A21="","",科目別集計!$A21) | V2: =IF(科目別集計!$A22="","",科目別集計!$A22) | W2: =IF(科目別集計!$A23="","",科目別集計!$A23) | X2: =IF(科目別集計!$A24="","",科目別集計!$A24) | Y2: =IF(科目別集計!$A25="","",科目別集計!$A25) | Z2: 備考
A3: =IF(支払先マスタ!A3="","",支払先マスタ!A3) | B3: =IF(COUNT(C3:Y3)=0,"",SUM(C3:Y3))
A4: =IF(支払先マスタ!A4="","",支払先マスタ!A4) | B4: =IF(COUNT(C4:Y4)=0,"",SUM(C4:Y4))
A5: =IF(支払先マスタ!A5="","",支払先マスタ!A5) | B5: =IF(COUNT(C5:Y5)=0,"",SUM(C5:Y5))
A6: =IF(支払先マスタ!A6="","",支払先マスタ!A6) | B6: =IF(COUNT(C6:Y6)=0,"",SUM(C6:Y6))
A7: =IF(支払先マスタ!A7="","",支払先マスタ!A7) | B7: =IF(COUNT(C7:Y7)=0,"",SUM(C7:Y7))
A8: =IF(支払先マスタ!A8="","",支払先マスタ!A8) | B8: =IF(COUNT(C8:Y8)=0,"",SUM(C8:Y8))
A9: =IF(支払先マスタ!A9="","",支払先マスタ!A9) | B9: =IF(COUNT(C9:Y9)=0,"",SUM(C9:Y9))
A10: =IF(支払先マスタ!A10="","",支払先マスタ!A10) | B10: =IF(COUNT(C10:Y10)=0,"",SUM(C10:Y10))
A11: =IF(支払先マスタ!A11="","",支払先マスタ!A11) | B11: =IF(COUNT(C11:Y11)=0,"",SUM(C11:Y11))
A12: =IF(支払先マスタ!A12="","",支払先マスタ!A12) | B12: =IF(COUNT(C12:Y12)=0,"",SUM(C12:Y12))
A13: =IF(支払先マスタ!A13="","",支払先マスタ!A13) | B13: =IF(COUNT(C13:Y13)=0,"",SUM(C13:Y13))
A14: =IF(支払先マスタ!A14="","",支払先マスタ!A14) | B14: =IF(COUNT(C14:Y14)=0,"",SUM(C14:Y14))
... A55: =IF(支払先マスタ!A55="","",支払先マスタ!A55) | B55: =IF(COUNT(C55:Y55)=0,"",SUM(C55:Y55))
A56: 合計 | B56: =IF(COUNT(B3:B55)=0,"",SUM(B3:B55)) | C56: =IF(COUNT(C3:C55)=0,"",SUM(C3:C55)) | D56: =IF(COUNT(D3:D55)=0,"",SUM(D3:D55)) | E56: =IF(COUNT(E3:E55)=0,"",SUM(E3:E55)) | F56: =IF(COUNT(F3:F55)=0,"",SUM(F3:F55)) | G56: =IF(COUNT(G3:G55)=0,"",SUM(G3:G55)) | H56: =IF(COUNT(H3:H55)=0,"",SUM(H3:H55)) | I56: =IF(COUNT(I3:I55)=0,"",SUM(I3:I55)) | ... Y56: =IF(COUNT(Y3:Y55)=0,"",SUM(Y3:Y55))

Sheet 支払先マスタ
A1: 支払先マスタ（ここに追記すると全ての月シートに行が増えます）
A2: 支払先 | B2: 勘定科目（区分） | C2: 銀行（参考） | D2: 備考 | E2: 媒体
A3: レオパレス２１ | B3: 賃借料 | C3: みずほ銀行 | E3: ダウンロード
A4: マサヨ(越谷) | B4: 賃借料 | C4: みずほ銀行 | D4: 駐車場 | E4: なし
A5: ヨシテル(越谷) | B5: 賃借料 | C5: みずほ銀行 | D5: 駐車場 | E5: なし
A6: ヨシテル(三郷) | B6: 賃借料 | C6: みずほ銀行 | D6: 駐車場 | E6: なし
A7: 中沢酒造株式会社 | B7: 賃借料 | C7: みずほ銀行 | D7: 前払い足柄店駐車場10台 | E7: なし
A8: 丸福企画 | B8: 賃借料 | C8: みずほ銀行 | D8: 駐車場 | E8: なし
A9: 豊田駐車場(孝司) | B9: 賃借料 | C9: みずほ銀行／武蔵野銀行 | D9: 駐車場 | E9: なし
A10: 山脇土地 | B10: 賃借料 | C10: みずほ銀行／武蔵野銀行 | D10: 駐車場 | E10: なし
A11: ヤナセ住販 | B11: 賃借料 | C11: みずほ銀行／武蔵野銀行 | D11: 駐車場 | E11: なし
A12: 大栄不動産 | B12: 賃借料 | C12: みずほ銀行／武蔵野銀行 | D12: 駐車場 | E12: なし
A13: 林 横浜駐車場 | B13: 賃借料 | C13: みずほ銀行／武蔵野銀行 | D13: 駐車場 | E13: なし
A14: 大東建託 | B14: 賃借料 | C14: みずほ銀行／武蔵野銀行 | D14: アパート | E14: なし
A15: 住友林業アーキテクノ | B15: 修繕費 | C15: みずほ銀行 | D15: ガス管破損修繕費用負担 8/5振込 | E15: 郵送
... A20: アンナカ | B20: 消耗品費 | C20: 武蔵野銀行 | D20: 測量機器 | E20: info@にメール
A21: GEプランニング | B21: 消耗品費 | C21: 武蔵野銀行 | D21: 地盤機器
A22: 埼玉測器社 | B22: 消耗品費 | C22: 武蔵野銀行 | D22: 測量機器 | E22: 郵送
A23: ワークマン吉川 | B23: 消耗品費 | C23: 武蔵野銀行 | D23: 作業着他 | E23: 郵送
A24: 三郷中央クリニック | B24: 雑費 | C24: みずほ銀行／武蔵野銀行 | D24: 産業医 | E24: なし
A25: ㈱オプティム | B25: 雑費 | C25: 武蔵野銀行 | D25: GEOスキャンライセンス | E25: 郵送
A26: 木下フレンド | B26: 雑費 | C26: 武蔵野銀行 | D26: 所沢産廃 | E26: メール
A27: 島村興産 | B27: 雑費 | C27: 武蔵野銀行 | D27: 三郷産廃 | E27: 郵送
A28: 地盤審査補償事業 | B28: 雑費 | C28: 武蔵野銀行 | D28: 物件登録料 | E28: 郵送
A29: 佐川急便 越谷 | B29: 通信費 | C29: みずほ銀行 | D29: みずほ第十集中 | E29: ダウンロード
A30: 佐川急便 所沢 | B30: 通信費 | C30: みずほ銀行 | E30: ダウンロード
A31: 佐川急便 横浜瀬谷 | B31: 通信費 | C31: みずほ銀行 | E31: ダウンロード
A32: レオパレスガス代 | B32: 水道光熱費 | C32: みずほ銀行 | E32: メール
A33: 明治安田生命保険料 | B33: 保険積立金 | C33: 武蔵野銀行 | E33: 郵送
A34: エリアフォース | B34: 広告宣伝費 | C34: 武蔵野銀行 | D34: Indeed Plus掲載 | E34: メールで問い合わせ中
A35: アスクル(プラスロジテクス) | B35: 複数科目 | C35: みずほ銀行 | D35: みずほ銀行 | E35: 郵送
A36: 小松車輛 | B36: 複数科目 | C36: 武蔵野銀行 | D36: 車両リース | E36: 郵送
A37: ニシネン砿油（セルヴィス） | B37: 複数科目 | C37: 武蔵野銀行 | D37: 車両修理 | E37: 郵送
A38: くるま屋 石本 | B38: 複数科目 | C38: 武蔵野銀行 | D38: 車両修理 | E38: 郵送
A39: エムエス測器 | B39: 複数科目 | C39: 武蔵野銀行 | E39: 郵送
A40: 滝本特殊溶接工業 | B40: 複数科目 | C40: 武蔵野銀行 | D40: 地盤機器修理 | E40: 郵送

Sheet 原本_みずほ銀行
A1: みずほ銀行
A3: 支払先 | B3: 勘定科目 | C3: ９月末 | D3: ８月末 | E3: ７月末 | F3: ６月末 | G3: 備考 | H3: 媒体
A4: 佐川急便 越谷 | B4: 通信費 | D4: 72056 | E4: 82367 | F4: 72308 | G4: みずほ第十集中 | H4: ダウンロード
A5: 佐川急便 所沢 | B5: 通信費 | D5: 2178 | H5: ダウンロード
A6: 佐川急便 横浜瀬谷 | B6: 通信費 | D6: 9974 | H6: ダウンロード
A7: アスクル(プラスロジテクス) | B7: 消耗品費 | D7: 160084 | E7: 102568 | F7: 93408 | G7: みずほ銀行 | H7: 郵送
B8: 消耗品費（8%） | E8: 66448
A9: レオパレス２１ | B9: 賃借料 | D9: 228360 | E9: 228360 | F9: 360195 | H9: ダウンロード
A10: レオパレスガス代 | B10: 水道光熱費 | D10: 14720 | E10: 18301 | F10: 17236 | H10: メール
A11: 住友林業アーキテクノ | B11: 修繕費 | D11: 35310 | G11: ガス管破損修繕費用負担 8/5振込 | H11: 郵送
A15: マサヨ(越谷) | B15: 賃借料 | C15: 382500 | D15: 382500 | E15: 382500 | F15: 382500 | G15: 駐車場 | H15: なし
A16: ヨシテル(越谷) | B16: 賃借料 | C16: 350000 | D16: 350000 | E16: 350000 | F16: 350000 | G16: 駐車場 | H16: なし
A17: ヨシテル(三郷) | B17: 賃借料 | C17: 390000 | D17: 390000 | E17: 390000 | F17: 390000 | G17: 駐車場 | H17: なし
A18: 中沢酒造株式会社 | B18: 賃借料 | C18: 60000 | D18: 60000 | E18: 60000 | F18: 60000 | G18: 前払い足柄店駐車場10台 | H18: なし
A19: 丸福企画 | B19: 賃借料 | C19: 170000 | D19: 170000 | E19: 170000 | F19: 170000 | G19: 駐車場 | H19: なし
A20: 豊田駐車場(孝司) | B20: 賃借料 | C20: 165000 | G20: 駐車場 | H20: なし
A21: 山脇土地 | B21: 賃借料 | C21: 55000 | G21: 駐車場 | H21: なし
A22: ヤナセ住販 | B22: 賃借料 | C22: 35200 | G22: 駐車場 | H22: なし
A23: 大栄不動産 | B23: 賃借料 | C23: 29700 | G23: 駐車場 | H23: なし
A24: 林 横浜駐車場 | B24: 賃借料 | C24: 90000 | G24: 駐車場 | H24: なし
A25: 大東建託 | B25: 賃借料 | C25: 67300 | G25: アパート | H25: なし
A26: 三郷中央クリニック | B26: 雑費 | C26: 60000 | G26: 産業医 | H26: なし
A30: 合計金額 | C30: =SUM(C4:C18) | D30: =SUM(D4:D18) | E30: =SUM(E4:E18) | F30: =SUM(F4:F18)
D31: =D30-D11 | G31: ガス管破損負担分を除いた額

Sheet 原本_武蔵野銀行
A1: 取引先 | B1: 勘定科目 | C1: ９月末 | D1: ８月末 | E1: ７月末 | F1: ６月末 | G1: 備考 | H1: 媒体
A2: 小松車輛 | C2: =C3+C4 | D2: =D3+D4 | E2: =E3+E4 | F2: =F3+F4 | H2: 郵送
B3: リース料 | D3: 849200 | E3: 849200 | F3: 849200 | G3: 車両リース
B4: 修繕費 | D4: 129494 | E4: 58410 | G4: 車両修理
A5: 梅田自動車 | C5: =C6+C7 | D5: =D6+D7 | E5: =E6+E7 | F5: =F6+F7 | H5: 郵送
B6: 修繕費 | D6: 1649540 | E6: 322350 | F6: 815100 | G6: 車両修理
B7: 車両運搬具
A8: ニシネン砿油（セルヴィス） | C8: =SUM(C9:C15) | D8: =SUM(D9:D15) | E8: =SUM(E9:E15) | F8: =SUM(F9:F15) | H8: 郵送
B9: 修繕費 | D9: 339900 | E9: 170800 | G9: 車両修理
B10: 保険料 | E10: 22400 | G10: 車検
B11: 租税公課
B12: 支払手数料 | E12: 23550
B13: 消耗品費 | E13: 124850
B14: 車両運搬具
B15: 車輛燃料費
A16: くるま屋 石本 | C16: =SUM(C17:C21) | D16: =SUM(D17:D21) | E16: =SUM(E17:E21) | F16: =SUM(F17:F21) | H16: 郵送
B17: 修繕費 | D17: 56760 | F17: 11300 | G17: 車両修理
B18: 保険料 | D18: 17540 | G18: 車検
B19: 租税公課 | D19: 7500
B20: 支払手数料 | D20: 8800
B21: 消耗品費
A22: 平田自動車工業㈱ | C22: =SUM(C23:C24) | D22: =SUM(D23:D24) | E22: =SUM(E23:E24) | F22: =SUM(F23:F24) | H22: 郵送
B23: 修繕費 | F23: 5500 | G23: 車両修理
B24: 消耗品費
A25: ㈱オプティム | C25: =SUM(C26:C27) | D25: =SUM(D26:D27) | E25: =SUM(E26:E27) | F25: =SUM(F26:F27) | H25: 郵送
B26: 雑費 | D26: 89100 | E26: 89100 | F26: 89100 | G26: GEOスキャンライセンス
B27: 工具、器具及び備品 | G27: GEOスキャン本体
A28: エムエス測器 | C28: =SUM(C29:C31) | D28: =SUM(D29:D31) | E28: =SUM(E29:E31) | F28: =SUM(F29:F31) | H28: 郵送
B29: 修繕費 | D29: 46200
B30: 消耗品費 | D30: 14300
B31: 工具、器具及び備品
A32: 滝本特殊溶接工業 | C32: =SUM(C33:C34) | D32: =SUM(D33:D34) | E32: =SUM(E33:E34) | F32: =SUM(F33:F34) | G32: 地盤機器修理 | H32: 郵送
B33: 修繕費 | F33: 34000
B34: 消耗品費 | E34: 8250
A35: アンナカ | C35: =SUM(C36:C37) | D35: =SUM(D36:D37) | E35: =SUM(E36:E37) | F35: =SUM(F36:F37) | H35: info@にメール
B36: 消耗品費 | D36: 461780 | E36: 288893 | F36: 190410
B37: 工具、器具及び備品 | G37: 測量機器
A38: GEプランニング | B38: 消耗品費 | E38: 550000 | G38: 地盤機器
A39: 日東精工 | B39: 修繕費 | D39: 485760 | F39: 685652 | G39: ジオカルテ修理 | H39: メール
A40: 埼玉測器社 | B40: 消耗品費 | D40: 155881 | E40: 103400 | F40: 79200 | G40: 測量機器 | H40: 郵送
...
